Workbook

Sheet Dashboard
AA1: 18/09/2026 | AB1: USD
B2: Tỷ giá ngoại tệ | AA2: 17/09/2026 | AB2: EUR
B3: Ngày xem | E3: So sánh với ngày | AA3: 16/09/2026 | AB3: GBP
B4: 18/09/2026 | C4: 📅 ← Chọn ngày | E4: 17/09/2026 | F4: 📅 ← So sánh | AA4: 15/09/2026 | AB4: JPY
AA5: 14/09/2026 | AB5: AUD
B6: Mã ngoại tệ | C6: Tên ngoại tệ | D6: Mua tiền mặt | E6: Mua chuyển khoản | F6: Bán | G6: Bình quân | H6: % Thay đổi | I6: Bán (SS) | J6: Chênh lệch | K6: % So sánh | AA6: 13/09/2026 | AB6: CAD
B7: USD | C7: =IFERROR(INDEX('_RateData'!$C$2:$C$258,MATCH($B$4,'_RateData'!$A$2:$A$258,0)),"-") | D7: =IFERROR(INDEX('_RateData'!$D$2:$D$258,MATCH($B$4,'_RateData'!$A$2:$A$258,0)),"-") | E7: =IFERROR(INDEX('_RateData'!$E$2:$E$258,MATCH($B$4,'_RateData'!$A$2:$A$258,0)),"-") | F7: =IFERROR(INDEX('_RateData'!$F$2:$F$258,MATCH($B$4,'_RateData'!$A$2:$A$258,0)),"-") | G7: =IFERROR(AVERAGE(E7,F7),"-") | H7: =IFERROR(IF(AND(ISNUMBER(F7),ISNUMBER(I7),I7<>0),(F7-I7)/I7*100,"-"),"-") | I7: =IFERROR(INDEX('_RateData'!$F$2:$F$258,MATCH($E$4,'_RateData'!$A$2:$A$258,0)),"-") | J7: =IFERROR(IF(AND(ISNUMBER(F7),ISNUMBER(I7)),F7-I7,"-"),"-") | K7: =IFERROR(IF(AND(ISNUMBER(F7),ISNUMBER(I7),I7<>0),(F7-I7)/I7*100,"-"),"-") | AA7: 12/09/2026 | AB7: CHF
B8: EUR | C8: =IFERROR(INDEX('_RateData'!$G$2:$G$258,MATCH($B$4,'_RateData'!$A$2:$A$258,0)),"-") | D8: =IFERROR(INDEX('_RateData'!$H$2:$H$258,MATCH($B$4,'_RateData'!$A$2:$A$258,0)),"-") | E8: =IFERROR(INDEX('_RateData'!$I$2:$I$258,MATCH($B$4,'_RateData'!$A$2:$A$258,0)),"-") | F8: =IFERROR(INDEX('_RateData'!$J$2:$J$258,MATCH($B$4,'_RateData'!$A$2:$A$258,0)),"-") | G8: =IFERROR(AVERAGE(E8,F8),"-") | H8: =IFERROR(IF(AND(ISNUMBER(F8),ISNUMBER(I8),I8<>0),(F8-I8)/I8*100,"-"),"-") | I8: =IFERROR(INDEX('_RateData'!$J$2:$J$258,MATCH($E$4,'_RateData'!$A$2:$A$258,0)),"-") | J8: =IFERROR(IF(AND(ISNUMBER(F8),ISNUMBER(I8)),F8-I8,"-"),"-") | K8: =IFERROR(IF(AND(ISNUMBER(F8),ISNUMBER(I8),I8<>0),(F8-I8)/I8*100,"-"),"-") | AA8: 11/09/2026 | AB8: SGD
B9: GBP | C9: =IFERROR(INDEX('_RateData'!$K$2:$K$258,MATCH($B$4,'_RateData'!$A$2:$A$258,0)),"-") | D9: =IFERROR(INDEX('_RateData'!$L$2:$L$258,MATCH($B$4,'_RateData'!$A$2:$A$258,0)),"-") | E9: =IFERROR(INDEX('_RateData'!$M$2:$M$258,MATCH($B$4,'_RateData'!$A$2:$A$258,0)),"-") | F9: =IFERROR(INDEX('_RateData'!$N$2:$N$258,MATCH($B$4,'_RateData'!$A$2:$A$258,0)),"-") | G9: =IFERROR(AVERAGE(E9,F9),"-") | H9: =IFERROR(IF(AND(ISNUMBER(F9),ISNUMBER(I9),I9<>0),(F9-I9)/I9*100,"-"),"-") | I9: =IFERROR(INDEX('_RateData'!$N$2:$N$258,MATCH($E$4,'_RateData'!$A$2:$A$258,0)),"-") | J9: =IFERROR(IF(AND(ISNUMBER(F9),ISNUMBER(I9)),F9-I9,"-"),"-") | K9: =IFERROR(IF(AND(ISNUMBER(F9),ISNUMBER(I9),I9<>0),(F9-I9)/I9*100,"-"),"-") | AA9: 10/09/2026 | AB9: CNY
B10: JPY | C10: =IFERROR(INDEX('_RateData'!$O$2:$O$258,MATCH($B$4,'_RateData'!$A$2:$A$258,0)),"-") | D10: =IFERROR(INDEX('_RateData'!$P$2:$P$258,MATCH($B$4,'_RateData'!$A$2:$A$258,0)),"-") | E10: =IFERROR(INDEX('_RateData'!$Q$2:$Q$258,MATCH($B$4,'_RateData'!$A$2:$A$258,0)),"-") | F10: =IFERROR(INDEX('_RateData'!$R$2:$R$258,MATCH($B$4,'_RateData'!$A$2:$A$258,0)),"-") | G10: =IFERROR(AVERAGE(E10,F10),"-") | H10: =IFERROR(IF(AND(ISNUMBER(F10),ISNUMBER(I10),I10<>0),(F10-I10)/I10*100,"-"),"-") | I10: =IFERROR(INDEX('_RateData'!$R$2:$R$258,MATCH($E$4,'_RateData'!$A$2:$A$258,0)),"-") | J10: =IFERROR(IF(AND(ISNUMBER(F10),ISNUMBER(I10)),F10-I10,"-"),"-") | K10: =IFERROR(IF(AND(ISNUMBER(F10),ISNUMBER(I10),I10<>0),(F10-I10)/I10*100,"-"),"-") | AA10: 09/09/2026 | AB10: HKD
B11: AUD | C11: =IFERROR(INDEX('_RateData'!$S$2:$S$258,MATCH($B$4,'_RateData'!$A$2:$A$258,0)),"-") | D11: =IFERROR(INDEX('_RateData'!$T$2:$T$258,MATCH($B$4,'_RateData'!$A$2:$A$258,0)),"-") | E11: =IFERROR(INDEX('_RateData'!$U$2:$U$258,MATCH($B$4,'_RateData'!$A$2:$A$258,0)),"-") | F11: =IFERROR(INDEX('_RateData'!$V$2:$V$258,MATCH($B$4,'_RateData'!$A$2:$A$258,0)),"-") | G11: =IFERROR(AVERAGE(E11,F11),"-") | H11: =IFERROR(IF(AND(ISNUMBER(F11),ISNUMBER(I11),I11<>0),(F11-I11)/I11*100,"-"),"-") | I11: =IFERROR(INDEX('_RateData'!$V$2:$V$258,MATCH($E$4,'_RateData'!$A$2:$A$258,0)),"-") | J11: =IFERROR(IF(AND(ISNUMBER(F11),ISNUMBER(I11)),F11-I11,"-"),"-") | K11: =IFERROR(IF(AND(ISNUMBER(F11),ISNUMBER(I11),I11<>0),(F11-I11)/I11*100,"-"),"-") | AA11: 08/09/2026 | AB11: THB
B12: CAD | C12: =IFERROR(INDEX('_RateData'!$W$2:$W$258,MATCH($B$4,'_RateData'!$A$2:$A$258,0)),"-") | D12: =IFERROR(INDEX('_RateData'!$X$2:$X$258,MATCH($B$4,'_RateData'!$A$2:$A$258,0)),"-") | E12: =IFERROR(INDEX('_RateData'!$Y$2:$Y$258,MATCH($B$4,'_RateData'!$A$2:$A$258,0)),"-") | F12: =IFERROR(INDEX('_RateData'!$Z$2:$Z$258,MATCH($B$4,'_RateData'!$A$2:$A$258,0)),"-") | G12: =IFERROR(AVERAGE(E12,F12),"-") | H12: =IFERROR(IF(AND(ISNUMBER(F12),ISNUMBER(I12),I12<>0),(F12-I12)/I12*100,"-"),"-") | I12: =IFERROR(INDEX('_RateData'!$Z$2:$Z$258,MATCH($E$4,'_RateData'!$A$2:$A$258,0)),"-") | J12: =IFERROR(IF(AND(ISNUMBER(F12),ISNUMBER(I12)),F12-I12,"-"),"-") | K12: =IFERROR(IF(AND(ISNUMBER(F12),ISNUMBER(I12),I12<>0),(F12-I12)/I12*100,"-"),"-") | AA12: 07/09/2026 | AB12: KRW
B13: CHF | C13: =IFERROR(INDEX('_RateData'!$AA$2:$AA$258,MATCH($B$4,'_RateData'!$A$2:$A$258,0)),"-") | D13: =IFERROR(INDEX('_RateData'!$AB$2:$AB$258,MATCH($B$4,'_RateData'!$A$2:$A$258,0)),"-") | E13: =IFERROR(INDEX('_RateData'!$AC$2:$AC$258,MATCH($B$4,'_RateData'!$A$2:$A$258,0)),"-") | F13: =IFERROR(INDEX('_RateData'!$AD$2:$AD$258,MATCH($B$4,'_RateData'!$A$2:$A$258,0)),"-") | G13: =IFERROR(AVERAGE(E13,F13),"-") | H13: =IFERROR(IF(AND(ISNUMBER(F13),ISNUMBER(I13),I13<>0),(F13-I13)/I13*100,"-"),"-") | I13: =IFERROR(INDEX('_RateData'!$AD$2:$AD$258,MATCH($E$4,'_RateData'!$A$2:$A$258,0)),"-") | J13: =IFERROR(IF(AND(ISNUMBER(F13),ISNUMBER(I13)),F13-I13,"-"),"-") | K13: =IFERROR(IF(AND(ISNUMBER(F13),ISNUMBER(I13),I13<>0),(F13-I13)/I13*100,"-"),"-") | AA13: 06/09/2026 | AB13: MYR
B14: SGD | C14: =IFERROR(INDEX('_RateData'!$AE$2:$AE$258,MATCH($B$4,'_RateData'!$A$2:$A$258,0)),"-") | D14: =IFERROR(INDEX('_RateData'!$AF$2:$AF$258,MATCH($B$4,'_RateData'!$A$2:$A$258,0)),"-") | E14: =IFERROR(INDEX('_RateData'!$AG$2:$AG$258,MATCH($B$4,'_RateData'!$A$2:$A$258,0)),"-") | F14: =IFERROR(INDEX('_RateData'!$AH$2:$AH$258,MATCH($B$4,'_RateData'!$A$2:$A$258,0)),"-") | G14: =IFERROR(AVERAGE(E14,F14),"-") | H14: =IFERROR(IF(AND(ISNUMBER(F14),ISNUMBER(I14),I14<>0),(F14-I14)/I14*100,"-"),"-") | I14: =IFERROR(INDEX('_RateData'!$AH$2:$AH$258,MATCH($E$4,'_RateData'!$A$2:$A$258,0)),"-") | J14: =IFERROR(IF(AND(ISNUMBER(F14),ISNUMBER(I14)),F14-I14,"-"),"-") | K14: =IFERROR(IF(AND(ISNUMBER(F14),ISNUMBER(I14),I14<>0),(F14-I14)/I14*100,"-"),"-") | AA14: 05/09/2026 | AB14: INR
B15: CNY | C15: =IFERROR(INDEX('_RateData'!$AI$2:$AI$258,MATCH($B$4,'_RateData'!$A$2:$A$258,0)),"-") | D15: =IFERROR(INDEX('_RateData'!$AJ$2:$AJ$258,MATCH($B$4,'_RateData'!$A$2:$A$258,0)),"-") | E15: =IFERROR(INDEX('_RateData'!$AK$2:$AK$258,MATCH($B$4,'_RateData'!$A$2:$A$258,0)),"-") | F15: =IFERROR(INDEX('_RateData'!$AL$2:$AL$258,MATCH($B$4,'_RateData'!$A$2:$A$258,0)),"-") | G15: =IFERROR(AVERAGE(E15,F15),"-") | H15: =IFERROR(IF(AND(ISNUMBER(F15),ISNUMBER(I15),I15<>0),(F15-I15)/I15*100,"-"),"-") | I15: =IFERROR(INDEX('_RateData'!$AL$2:$AL$258,MATCH($E$4,'_RateData'!$A$2:$A$258,0)),"-") | J15: =IFERROR(IF(AND(ISNUMBER(F15),ISNUMBER(I15)),F15-I15,"-"),"-") | K15: =IFERROR(IF(AND(ISNUMBER(F15),ISNUMBER(I15),I15<>0),(F15-I15)/I15*100,"-"),"-") | AA15: 04/09/2026 | AB15: KWD
B16: HKD | C16: =IFERROR(INDEX('_RateData'!$AM$2:$AM$258,MATCH($B$4,'_RateData'!$A$2:$A$258,0)),"-") | D16: =IFERROR(INDEX('_RateData'!$AN$2:$AN$258,MATCH($B$4,'_RateData'!$A$2:$A$258,0)),"-") | E16: =IFERROR(INDEX('_RateData'!$AO$2:$AO$258,MATCH($B$4,'_RateData'!$A$2:$A$258,0)),"-") | F16: =IFERROR(INDEX('_RateData'!$AP$2:$AP$258,MATCH($B$4,'_RateData'!$A$2:$A$258,0)),"-") | G16: =IFERROR(AVERAGE(E16,F16),"-") | H16: =IFERROR(IF(AND(ISNUMBER(F16),ISNUMBER(I16),I16<>0),(F16-I16)/I16*100,"-"),"-") | I16: =IFERROR(INDEX('_RateData'!$AP$2:$AP$258,MATCH($E$4,'_RateData'!$A$2:$A$258,0)),"-") | J16: =IFERROR(IF(AND(ISNUMBER(F16),ISNUMBER(I16)),F16-I16,"-"),"-") | K16: =IFERROR(IF(AND(ISNUMBER(F16),ISNUMBER(I16),I16<>0),(F16-I16)/I16*100,"-"),"-") | AA16: 03/09/2026 | AB16: SAR
B17: THB | C17: =IFERROR(INDEX('_RateData'!$AQ$2:$AQ$258,MATCH($B$4,'_RateData'!$A$2:$A$258,0)),"-") | D17: =IFERROR(INDEX('_RateData'!$AR$2:$AR$258,MATCH($B$4,'_RateData'!$A$2:$A$258,0)),"-") | E17: =IFERROR(INDEX('_RateData'!$AS$2:$AS$258,MATCH($B$4,'_RateData'!$A$2:$A$258,0)),"-") | F17: =IFERROR(INDEX('_RateData'!$AT$2:$AT$258,MATCH($B$4,'_RateData'!$A$2:$A$258,0)),"-") | G17: =IFERROR(AVERAGE(E17,F17),"-") | H17: =IFERROR(IF(AND(ISNUMBER(F17),ISNUMBER(I17),I17<>0),(F17-I17)/I17*100,"-"),"-") | I17: =IFERROR(INDEX('_RateData'!$AT$2:$AT$258,MATCH($E$4,'_RateData'!$A$2:$A$258,0)),"-") | J17: =IFERROR(IF(AND(ISNUMBER(F17),ISNUMBER(I17)),F17-I17,"-"),"-") | K17: =IFERROR(IF(AND(ISNUMBER(F17),ISNUMBER(I17),I17<>0),(F17-I17)/I17*100,"-"),"-") | AA17: 02/09/2026 | AB17: NOK
B18: KRW | C18: =IFERROR(INDEX('_RateData'!$AU$2:$AU$258,MATCH($B$4,'_RateData'!$A$2:$A$258,0)),"-") | D18: =IFERROR(INDEX('_RateData'!$AV$2:$AV$258,MATCH($B$4,'_RateData'!$A$2:$A$258,0)),"-") | E18: =IFERROR(INDEX('_RateData'!$AW$2:$AW$258,MATCH($B$4,'_RateData'!$A$2:$A$258,0)),"-") | F18: =IFERROR(INDEX('_RateData'!$AX$2:$AX$258,MATCH($B$4,'_RateData'!$A$2:$A$258,0)),"-") | G18: =IFERROR(AVERAGE(E18,F18),"-") | H18: =IFERROR(IF(AND(ISNUMBER(F18),ISNUMBER(I18),I18<>0),(F18-I18)/I18*100,"-"),"-") | I18: =IFERROR(INDEX('_RateData'!$AX$2:$AX$258,MATCH($E$4,'_RateData'!$A$2:$A$258,0)),"-") | J18: =IFERROR(IF(AND(ISNUMBER(F18),ISNUMBER(I18)),F18-I18,"-"),"-") | K18: =IFERROR(IF(AND(ISNUMBER(F18),ISNUMBER(I18),I18<>0),(F18-I18)/I18*100,"-"),"-") | AA18: 01/09/2026 | AB18: SEK
B19: MYR | C19: =IFERROR(INDEX('_RateData'!$AY$2:$AY$258,MATCH($B$4,'_RateData'!$A$2:$A$258,0)),"-") | D19: =IFERROR(INDEX('_RateData'!$AZ$2:$AZ$258,MATCH($B$4,'_RateData'!$A$2:$A$258,0)),"-") | E19: =IFERROR(INDEX('_RateData'!$BA$2:$BA$258,MATCH($B$4,'_RateData'!$A$2:$A$258,0)),"-") | F19: =IFERROR(INDEX('_RateData'!$BB$2:$BB$258,MATCH($B$4,'_RateData'!$A$2:$A$258,0)),"-") | G19: =IFERROR(AVERAGE(E19,F19),"-") | H19: =IFERROR(IF(AND(ISNUMBER(F19),ISNUMBER(I19),I19<>0),(F19-I19)/I19*100,"-"),"-") | I19: =IFERROR(INDEX('_RateData'!$BB$2:$BB$258,MATCH($E$4,'_RateData'!$A$2:$A$258,0)),"-") | J19: =IFERROR(IF(AND(ISNUMBER(F19),ISNUMBER(I19)),F19-I19,"-"),"-") | K19: =IFERROR(IF(AND(ISNUMBER(F19),ISNUMBER(I19),I19<>0),(F19-I19)/I19*100,"-"),"-") | AA19: 31/08/2026 | AB19: DKK
B20: INR | C20: =IFERROR(INDEX('_RateData'!$BC$2:$BC$258,MATCH($B$4,'_RateData'!$A$2:$A$258,0)),"-") | D20: =IFERROR(INDEX('_RateData'!$BD$2:$BD$258,MATCH($B$4,'_RateData'!$A$2:$A$258,0)),"-") | E20: =IFERROR(INDEX('_RateData'!$BE$2:$BE$258,MATCH($B$4,'_RateData'!$A$2:$A$258,0)),"-") | F20: =IFERROR(INDEX('_RateData'!$BF$2:$BF$258,MATCH($B$4,'_RateData'!$A$2:$A$258,0)),"-") | G20: =IFERROR(AVERAGE(E20,F20),"-") | H20: =IFERROR(IF(AND(ISNUMBER(F20),ISNUMBER(I20),I20<>0),(F20-I20)/I20*100,"-"),"-") | I20: =IFERROR(INDEX('_RateData'!$BF$2:$BF$258,MATCH($E$4,'_RateData'!$A$2:$A$258,0)),"-") | J20: =IFERROR(IF(AND(ISNUMBER(F20),ISNUMBER(I20)),F20-I20,"-"),"-") | K20: =IFERROR(IF(AND(ISNUMBER(F20),ISNUMBER(I20),I20<>0),(F20-I20)/I20*100,"-"),"-") | AA20: 30/08/2026 | AB20: RUB
B21: KWD | C21: =IFERROR(INDEX('_RateData'!$BG$2:$BG$258,MATCH($B$4,'_RateData'!$A$2:$A$258,0)),"-") | D21: =IFERROR(INDEX('_RateData'!$BH$2:$BH$258,MATCH($B$4,'_RateData'!$A$2:$A$258,0)),"-") | E21: =IFERROR(INDEX('_RateData'!$BI$2:$BI$258,MATCH($B$4,'_RateData'!$A$2:$A$258,0)),"-") | F21: =IFERROR(INDEX('_RateData'!$BJ$2:$BJ$258,MATCH($B$4,'_RateData'!$A$2:$A$258,0)),"-") | G21: =IFERROR(AVERAGE(E21,F21),"-") | H21: =IFERROR(IF(AND(ISNUMBER(F21),ISNUMBER(I21),I21<>0),(F21-I21)/I21*100,"-"),"-") | I21: =IFERROR(INDEX('_RateData'!$BJ$2:$BJ$258,MATCH($E$4,'_RateData'!$A$2:$A$258,0)),"-") | J21: =IFERROR(IF(AND(ISNUMBER(F21),ISNUMBER(I21)),F21-I21,"-"),"-") | K21: =IFERROR(IF(AND(ISNUMBER(F21),ISNUMBER(I21),I21<>0),(F21-I21)/I21*100,"-"),"-") | AA21: 29/08/2026
B22: SAR | C22: =IFERROR(INDEX('_RateData'!$BK$2:$BK$258,MATCH($B$4,'_RateData'!$A$2:$A$258,0)),"-") | D22: =IFERROR(INDEX('_RateData'!$BL$2:$BL$258,MATCH($B$4,'_RateData'!$A$2:$A$258,0)),"-") | E22: =IFERROR(INDEX('_RateData'!$BM$2:$BM$258,MATCH($B$4,'_RateData'!$A$2:$A$258,0)),"-") | F22: =IFERROR(INDEX('_RateData'!$BN$2:$BN$258,MATCH($B$4,'_RateData'!$A$2:$A$258,0)),"-") | G22: =IFERROR(AVERAGE(E22,F22),"-") | H22: =IFERROR(IF(AND(ISNUMBER(F22),ISNUMBER(I22),I22<>0),(F22-I22)/I22*100,"-"),"-") | I22: =IFERROR(INDEX('_RateData'!$BN$2:$BN$258,MATCH($E$4,'_RateData'!$A$2:$A$258,0)),"-") | J22: =IFERROR(IF(AND(ISNUMBER(F22),ISNUMBER(I22)),F22-I22,"-"),"-") | K22: =IFERROR(IF(AND(ISNUMBER(F22),ISNUMBER(I22),I22<>0),(F22-I22)/I22*100,"-"),"-") | AA22: 28/08/2026
B23: NOK | C23: =IFERROR(INDEX('_RateData'!$BO$2:$BO$258,MATCH($B$4,'_RateData'!$A$2:$A$258,0)),"-") | D23: =IFERROR(INDEX('_RateData'!$BP$2:$BP$258,MATCH($B$4,'_RateData'!$A$2:$A$258,0)),"-") | E23: =IFERROR(INDEX('_RateData'!$BQ$2:$BQ$258,MATCH($B$4,'_RateData'!$A$2:$A$258,0)),"-") | F23: =IFERROR(INDEX('_RateData'!$BR$2:$BR$258,MATCH($B$4,'_RateData'!$A$2:$A$258,0)),"-") | G23: =IFERROR(AVERAGE(E23,F23),"-") | H23: =IFERROR(IF(AND(ISNUMBER(F23),ISNUMBER(I23),I23<>0),(F23-I23)/I23*100,"-"),"-") | I23: =IFERROR(INDEX('_RateData'!$BR$2:$BR$258,MATCH($E$4,'_RateData'!$A$2:$A$258,0)),"-") | J23: =IFERROR(IF(AND(ISNUMBER(F23),ISNUMBER(I23)),F23-I23,"-"),"-") | K23: =IFERROR(IF(AND(ISNUMBER(F23),ISNUMBER(I23),I23<>0),(F23-I23)/I23*100,"-"),"-") | AA23: 27/08/2026
B24: SEK | C24: =IFERROR(INDEX('_RateData'!$BS$2:$BS$258,MATCH($B$4,'_RateData'!$A$2:$A$258,0)),"-") | D24: =IFERROR(INDEX('_RateData'!$BT$2:$BT$258,MATCH($B$4,'_RateData'!$A$2:$A$258,0)),"-") | E24: =IFERROR(INDEX('_RateData'!$BU$2:$BU$258,MATCH($B$4,'_RateData'!$A$2:$A$258,0)),"-") | F24: =IFERROR(INDEX('_RateData'!$BV$2:$BV$258,MATCH($B$4,'_RateData'!$A$2:$A$258,0)),"-") | G24: =IFERROR(AVERAGE(E24,F24),"-") | H24: =IFERROR(IF(AND(ISNUMBER(F24),ISNUMBER(I24),I24<>0),(F24-I24)/I24*100,"-"),"-") | I24: =IFERROR(INDEX('_RateData'!$BV$2:$BV$258,MATCH($E$4,'_RateData'!$A$2:$A$258,0)),"-") | J24: =IFERROR(IF(AND(ISNUMBER(F24),ISNUMBER(I24)),F24-I24,"-"),"-") | K24: =IFERROR(IF(AND(ISNUMBER(F24),ISNUMBER(I24),I24<>0),(F24-I24)/I24*100,"-"),"-") | AA24: 26/08/2026
B25: DKK | C25: =IFERROR(INDEX('_RateData'!$BW$2:$BW$258,MATCH($B$4,'_RateData'!$A$2:$A$258,0)),"-") | D25: =IFERROR(INDEX('_RateData'!$BX$2:$BX$258,MATCH($B$4,'_RateData'!$A$2:$A$258,0)),"-") | E25: =IFERROR(INDEX('_RateData'!$BY$2:$BY$258,MATCH($B$4,'_RateData'!$A$2:$A$258,0)),"-") | F25: =IFERROR(INDEX('_RateData'!$BZ$2:$BZ$258,MATCH($B$4,'_RateData'!$A$2:$A$258,0)),"-") | G25: =IFERROR(AVERAGE(E25,F25),"-") | H25: =IFERROR(IF(AND(ISNUMBER(F25),ISNUMBER(I25),I25<>0),(F25-I25)/I25*100,"-"),"-") | I25: =IFERROR(INDEX('_RateData'!$BZ$2:$BZ$258,MATCH($E$4,'_RateData'!$A$2:$A$258,0)),"-") | J25: =IFERROR(IF(AND(ISNUMBER(F25),ISNUMBER(I25)),F25-I25,"-"),"-") | K25: =IFERROR(IF(AND(ISNUMBER(F25),ISNUMBER(I25),I25<>0),(F25-I25)/I25*100,"-"),"-") | AA25: 25/08/2026
B26: RUB | C26: =IFERROR(INDEX('_RateData'!$CA$2:$CA$258,MATCH($B$4,'_RateData'!$A$2:$A$258,0)),"-") | D26: =IFERROR(INDEX('_RateData'!$CB$2:$CB$258,MATCH($B$4,'_RateData'!$A$2:$A$258,0)),"-") | E26: =IFERROR(INDEX('_RateData'!$CC$2:$CC$258,MATCH($B$4,'_RateData'!$A$2:$A$258,0)),"-") | F26: =IFERROR(INDEX('_RateData'!$CD$2:$CD$258,MATCH($B$4,'_RateData'!$A$2:$A$258,0)),"-") | G26: =IFERROR(AVERAGE(E26,F26),"-") | H26: =IFERROR(IF(AND(ISNUMBER(F26),ISNUMBER(I26),I26<>0),(F26-I26)/I26*100,"-"),"-") | I26: =IFERROR(INDEX('_RateData'!$CD$2:$CD$258,MATCH($E$4,'_RateData'!$A$2:$A$258,0)),"-") | J26: =IFERROR(IF(AND(ISNUMBER(F26),ISNUMBER(I26)),F26-I26,"-"),"-") | K26: =IFERROR(IF(AND(ISNUMBER(F26),ISNUMBER(I26),I26<>0),(F26-I26)/I26*100,"-"),"-") | AA26: 24/08/2026
AA27: 23/08/2026
AA28: 22/08/2026
B29: 📈 Biểu đồ biến động tỷ giá (TB tháng) | AA29: 21/08/2026
B30: Chọn ngoại tệ: | C30: USD | AA30: 20/08/2026
AA31: 19/08/2026
B32: Tháng | C32: Giá Bán (TB) | AA32: 18/08/2026
B33: 2026-01 | C33: =IFERROR(INDEX('_ChartData'!$A$2:$U$2,1,MATCH($C$30,'_ChartData'!$B$1:$U$1,0)),"-") | AA33: 17/08/2026
B34: 2026-02 | C34: =IFERROR(INDEX('_ChartData'!$A$3:$U$3,1,MATCH($C$30,'_ChartData'!$B$1:$U$1,0)),"-") | AA34: 16/08/2026
B35: 2026-03 | C35: =IFERROR(INDEX('_ChartData'!$A$4:$U$4,1,MATCH($C$30,'_ChartData'!$B$1:$U$1,0)),"-") | AA35: 15/08/2026
B36: 2026-04 | C36: =IFERROR(INDEX('_ChartData'!$A$5:$U$5,1,MATCH($C$30,'_ChartData'!$B$1:$U$1,0)),"-") | AA36: 14/08/2026
B37: 2026-05 | C37: =IFERROR(INDEX('_ChartData'!$A$6:$U$6,1,MATCH($C$30,'_ChartData'!$B$1:$U$1,0)),"-") | AA37: 13/08/2026
B38: 2026-06 | C38: =IFERROR(INDEX('_ChartData'!$A$7:$U$7,1,MATCH($C$30,'_ChartData'!$B$1:$U$1,0)),"-") | AA38: 12/08/2026
B39: 2026-07 | C39: =IFERROR(INDEX('_ChartData'!$A$8:$U$8,1,MATCH($C$30,'_ChartData'!$B$1:$U$1,0)),"-") | AA39: 11/08/2026
B40: 2026-08 | C40: =IFERROR(INDEX('_ChartData'!$A$9:$U$9,1,MATCH($C$30,'_ChartData'!$B$1:$U$1,0)),"-") | AA40: 10/08/2026
...

Sheet TheoDoi_USD
AA1: 18/09/2026
B2: BẢNG ĐIỀU HÀNH TỶ GIÁ USD/VND (EXECUTIVE DASHBOARD) | AA2: 17/09/2026
B3: Theo dõi, phân tích và so sánh biến động tỷ giá giữa 15 ngân hàng thương mại hàng đầu Việt Nam | AA3: 16/09/2026
B4: 18/09/2026 | C4: 📅 Ngày xem tỷ giá | E4: 17/09/2026 | F4: 📅 So sánh với ngày | H4: 🏛️ Quy mô: 15 Ngân hàng | AA4: 15/09/2026
AA5: 14/09/2026
B6: 🏆 BÁN THẤP NHẤT (MUA TỐT) | D6: 💰 MUA TIỀN MẶT CAO NHẤT | F6: 💳 MUA CHUYỂN KHOẢN CAO NHẤT | H6: 📊 SPREAD MUA - BÁN TB | AA6: 13/09/2026
B7: =MIN(E12:E26) | D7: =MAX(C12:C26) | F7: =MAX(D12:D26) | H7: =AVERAGE(F12:F26) | AA7: 12/09/2026
B8: =CONCATENATE("Tại: ", INDEX(B12:B26, MATCH(MIN(E12:E26), E12:E26, 0))) | D8: =CONCATENATE("Tại: ", INDEX(B12:B26, MATCH(MAX(C12:C26), C12:C26, 0))) | F8: =CONCATENATE("Tại: ", INDEX(B12:B26, MATCH(MAX(D12:D26), D12:D26, 0))) | H8: Chênh lệch trung bình thị trường | AA8: 11/09/2026
AA9: 10/09/2026
B10: 📋 MA TRẬN SO SÁNH TỶ GIÁ CHI TIẾT 15 NGÂN HÀNG | AA10: 09/09/2026
B11: Ngân hàng | C11: Mua tiền mặt | D11: Mua chuyển khoản | E11: Bán | F11: Chênh lệch Mua-Bán | G11: Bán (SS) | H11: Chênh lệch | I11: % So sánh | AA11: 08/09/2026
B12: Vietcombank | C12: =IF(SUMIFS(Data_TheoDoi_USD!$C$2:$C$10000, Data_TheoDoi_USD!$A$2:$A$10000, $B$4, Data_TheoDoi_USD!$B$2:$B$10000, $B12)=0, "-", SUMIFS(Data_TheoDoi_USD!$C$2:$C$10000, Data_TheoDoi_USD!$A$2:$A$10000, $B$4, Data_TheoDoi_USD!$B$2:$B$10000, $B12)) | D12: =IF(SUMIFS(Data_TheoDoi_USD!$D$2:$D$10000, Data_TheoDoi_USD!$A$2:$A$10000, $B$4, Data_TheoDoi_USD!$B$2:$B$10000, $B12)=0, "-", SUMIFS(Data_TheoDoi_USD!$D$2:$D$10000, Data_TheoDoi_USD!$A$2:$A$10000, $B$4, Data_TheoDoi_USD!$B$2:$B$10000, $B12)) | E12: =IF(SUMIFS(Data_TheoDoi_USD!$E$2:$E$10000, Data_TheoDoi_USD!$A$2:$A$10000, $B$4, Data_TheoDoi_USD!$B$2:$B$10000, $B12)=0, "-", SUMIFS(Data_TheoDoi_USD!$E$2:$E$10000, Data_TheoDoi_USD!$A$2:$A$10000, $B$4, Data_TheoDoi_USD!$B$2:$B$10000, $B12)) | F12: =IF(AND(ISNUMBER(E12), ISNUMBER(D12)), E12-D12, "-") | G12: =IF(SUMIFS(Data_TheoDoi_USD!$E$2:$E$10000, Data_TheoDoi_USD!$A$2:$A$10000, $E$4, Data_TheoDoi_USD!$B$2:$B$10000, $B12)=0, "-", SUMIFS(Data_TheoDoi_USD!$E$2:$E$10000, Data_TheoDoi_USD!$A$2:$A$10000, $E$4, Data_TheoDoi_USD!$B$2:$B$10000, $B12)) | H12: =IF(AND(ISNUMBER(E12), ISNUMBER(G12)), E12-G12, "-") | I12: =IF(AND(ISNUMBER(E12), ISNUMBER(G12), G12<>0), (E12-G12)/G12*100, "-") | AA12: 07/09/2026
B13: VietinBank | C13: =IF(SUMIFS(Data_TheoDoi_USD!$C$2:$C$10000, Data_TheoDoi_USD!$A$2:$A$10000, $B$4, Data_TheoDoi_USD!$B$2:$B$10000, $B13)=0, "-", SUMIFS(Data_TheoDoi_USD!$C$2:$C$10000, Data_TheoDoi_USD!$A$2:$A$10000, $B$4, Data_TheoDoi_USD!$B$2:$B$10000, $B13)) | D13: =IF(SUMIFS(Data_TheoDoi_USD!$D$2:$D$10000, Data_TheoDoi_USD!$A$2:$A$10000, $B$4, Data_TheoDoi_USD!$B$2:$B$10000, $B13)=0, "-", SUMIFS(Data_TheoDoi_USD!$D$2:$D$10000, Data_TheoDoi_USD!$A$2:$A$10000, $B$4, Data_TheoDoi_USD!$B$2:$B$10000, $B13)) | E13: =IF(SUMIFS(Data_TheoDoi_USD!$E$2:$E$10000, Data_TheoDoi_USD!$A$2:$A$10000, $B$4, Data_TheoDoi_USD!$B$2:$B$10000, $B13)=0, "-", SUMIFS(Data_TheoDoi_USD!$E$2:$E$10000, Data_TheoDoi_USD!$A$2:$A$10000, $B$4, Data_TheoDoi_USD!$B$2:$B$10000, $B13)) | F13: =IF(AND(ISNUMBER(E13), ISNUMBER(D13)), E13-D13, "-") | G13: =IF(SUMIFS(Data_TheoDoi_USD!$E$2:$E$10000, Data_TheoDoi_USD!$A$2:$A$10000, $E$4, Data_TheoDoi_USD!$B$2:$B$10000, $B13)=0, "-", SUMIFS(Data_TheoDoi_USD!$E$2:$E$10000, Data_TheoDoi_USD!$A$2:$A$10000, $E$4, Data_TheoDoi_USD!$B$2:$B$10000, $B13)) | H13: =IF(AND(ISNUMBER(E13), ISNUMBER(G13)), E13-G13, "-") | I13: =IF(AND(ISNUMBER(E13), ISNUMBER(G13), G13<>0), (E13-G13)/G13*100, "-") | AA13: 06/09/2026
B14: BIDV | C14: =IF(SUMIFS(Data_TheoDoi_USD!$C$2:$C$10000, Data_TheoDoi_USD!$A$2:$A$10000, $B$4, Data_TheoDoi_USD!$B$2:$B$10000, $B14)=0, "-", SUMIFS(Data_TheoDoi_USD!$C$2:$C$10000, Data_TheoDoi_USD!$A$2:$A$10000, $B$4, Data_TheoDoi_USD!$B$2:$B$10000, $B14)) | D14: =IF(SUMIFS(Data_TheoDoi_USD!$D$2:$D$10000, Data_TheoDoi_USD!$A$2:$A$10000, $B$4, Data_TheoDoi_USD!$B$2:$B$10000, $B14)=0, "-", SUMIFS(Data_TheoDoi_USD!$D$2:$D$10000, Data_TheoDoi_USD!$A$2:$A$10000, $B$4, Data_TheoDoi_USD!$B$2:$B$10000, $B14)) | E14: =IF(SUMIFS(Data_TheoDoi_USD!$E$2:$E$10000, Data_TheoDoi_USD!$A$2:$A$10000, $B$4, Data_TheoDoi_USD!$B$2:$B$10000, $B14)=0, "-", SUMIFS(Data_TheoDoi_USD!$E$2:$E$10000, Data_TheoDoi_USD!$A$2:$A$10000, $B$4, Data_TheoDoi_USD!$B$2:$B$10000, $B14)) | F14: =IF(AND(ISNUMBER(E14), ISNUMBER(D14)), E14-D14, "-") | G14: =IF(SUMIFS(Data_TheoDoi_USD!$E$2:$E$10000, Data_TheoDoi_USD!$A$2:$A$10000, $E$4, Data_TheoDoi_USD!$B$2:$B$10000, $B14)=0, "-", SUMIFS(Data_TheoDoi_USD!$E$2:$E$10000, Data_TheoDoi_USD!$A$2:$A$10000, $E$4, Data_TheoDoi_USD!$B$2:$B$10000, $B14)) | H14: =IF(AND(ISNUMBER(E14), ISNUMBER(G14)), E14-G14, "-") | I14: =IF(AND(ISNUMBER(E14), ISNUMBER(G14), G14<>0), (E14-G14)/G14*100, "-") | AA14: 05/09/2026
B15: Agribank | C15: =IF(SUMIFS(Data_TheoDoi_USD!$C$2:$C$10000, Data_TheoDoi_USD!$A$2:$A$10000, $B$4, Data_TheoDoi_USD!$B$2:$B$10000, $B15)=0, "-", SUMIFS(Data_TheoDoi_USD!$C$2:$C$10000, Data_TheoDoi_USD!$A$2:$A$10000, $B$4, Data_TheoDoi_USD!$B$2:$B$10000, $B15)) | D15: =IF(SUMIFS(Data_TheoDoi_USD!$D$2:$D$10000, Data_TheoDoi_USD!$A$2:$A$10000, $B$4, Data_TheoDoi_USD!$B$2:$B$10000, $B15)=0, "-", SUMIFS(Data_TheoDoi_USD!$D$2:$D$10000, Data_TheoDoi_USD!$A$2:$A$10000, $B$4, Data_TheoDoi_USD!$B$2:$B$10000, $B15)) | E15: =IF(SUMIFS(Data_TheoDoi_USD!$E$2:$E$10000, Data_TheoDoi_USD!$A$2:$A$10000, $B$4, Data_TheoDoi_USD!$B$2:$B$10000, $B15)=0, "-", SUMIFS(Data_TheoDoi_USD!$E$2:$E$10000, Data_TheoDoi_USD!$A$2:$A$10000, $B$4, Data_TheoDoi_USD!$B$2:$B$10000, $B15)) | F15: =IF(AND(ISNUMBER(E15), ISNUMBER(D15)), E15-D15, "-") | G15: =IF(SUMIFS(Data_TheoDoi_USD!$E$2:$E$10000, Data_TheoDoi_USD!$A$2:$A$10000, $E$4, Data_TheoDoi_USD!$B$2:$B$10000, $B15)=0, "-", SUMIFS(Data_TheoDoi_USD!$E$2:$E$10000, Data_TheoDoi_USD!$A$2:$A$10000, $E$4, Data_TheoDoi_USD!$B$2:$B$10000, $B15)) | H15: =IF(AND(ISNUMBER(E15), ISNUMBER(G15)), E15-G15, "-") | I15: =IF(AND(ISNUMBER(E15), ISNUMBER(G15), G15<>0), (E15-G15)/G15*100, "-") | AA15: 04/09/2026
B16: Techcombank | C16: =IF(SUMIFS(Data_TheoDoi_USD!$C$2:$C$10000, Data_TheoDoi_USD!$A$2:$A$10000, $B$4, Data_TheoDoi_USD!$B$2:$B$10000, $B16)=0, "-", SUMIFS(Data_TheoDoi_USD!$C$2:$C$10000, Data_TheoDoi_USD!$A$2:$A$10000, $B$4, Data_TheoDoi_USD!$B$2:$B$10000, $B16)) | D16: =IF(SUMIFS(Data_TheoDoi_USD!$D$2:$D$10000, Data_TheoDoi_USD!$A$2:$A$10000, $B$4, Data_TheoDoi_USD!$B$2:$B$10000, $B16)=0, "-", SUMIFS(Data_TheoDoi_USD!$D$2:$D$10000, Data_TheoDoi_USD!$A$2:$A$10000, $B$4, Data_TheoDoi_USD!$B$2:$B$10000, $B16)) | E16: =IF(SUMIFS(Data_TheoDoi_USD!$E$2:$E$10000, Data_TheoDoi_USD!$A$2:$A$10000, $B$4, Data_TheoDoi_USD!$B$2:$B$10000, $B16)=0, "-", SUMIFS(Data_TheoDoi_USD!$E$2:$E$10000, Data_TheoDoi_USD!$A$2:$A$10000, $B$4, Data_TheoDoi_USD!$B$2:$B$10000, $B16)) | F16: =IF(AND(ISNUMBER(E16), ISNUMBER(D16)), E16-D16, "-") | G16: =IF(SUMIFS(Data_TheoDoi_USD!$E$2:$E$10000, Data_TheoDoi_USD!$A$2:$A$10000, $E$4, Data_TheoDoi_USD!$B$2:$B$10000, $B16)=0, "-", SUMIFS(Data_TheoDoi_USD!$E$2:$E$10000, Data_TheoDoi_USD!$A$2:$A$10000, $E$4, Data_TheoDoi_USD!$B$2:$B$10000, $B16)) | H16: =IF(AND(ISNUMBER(E16), ISNUMBER(G16)), E16-G16, "-") | I16: =IF(AND(ISNUMBER(E16), ISNUMBER(G16), G16<>0), (E16-G16)/G16*100, "-") | AA16: 03/09/2026
B17: ACB | C17: =IF(SUMIFS(Data_TheoDoi_USD!$C$2:$C$10000, Data_TheoDoi_USD!$A$2:$A$10000, $B$4, Data_TheoDoi_USD!$B$2:$B$10000, $B17)=0, "-", SUMIFS(Data_TheoDoi_USD!$C$2:$C$10000, Data_TheoDoi_USD!$A$2:$A$10000, $B$4, Data_TheoDoi_USD!$B$2:$B$10000, $B17)) | D17: =IF(SUMIFS(Data_TheoDoi_USD!$D$2:$D$10000, Data_TheoDoi_USD!$A$2:$A$10000, $B$4, Data_TheoDoi_USD!$B$2:$B$10000, $B17)=0, "-", SUMIFS(Data_TheoDoi_USD!$D$2:$D$10000, Data_TheoDoi_USD!$A$2:$A$10000, $B$4, Data_TheoDoi_USD!$B$2:$B$10000, $B17)) | E17: =IF(SUMIFS(Data_TheoDoi_USD!$E$2:$E$10000, Data_TheoDoi_USD!$A$2:$A$10000, $B$4, Data_TheoDoi_USD!$B$2:$B$10000, $B17)=0, "-", SUMIFS(Data_TheoDoi_USD!$E$2:$E$10000, Data_TheoDoi_USD!$A$2:$A$10000, $B$4, Data_TheoDoi_USD!$B$2:$B$10000, $B17)) | F17: =IF(AND(ISNUMBER(E17), ISNUMBER(D17)), E17-D17, "-") | G17: =IF(SUMIFS(Data_TheoDoi_USD!$E$2:$E$10000, Data_TheoDoi_USD!$A$2:$A$10000, $E$4, Data_TheoDoi_USD!$B$2:$B$10000, $B17)=0, "-", SUMIFS(Data_TheoDoi_USD!$E$2:$E$10000, Data_TheoDoi_USD!$A$2:$A$10000, $E$4, Data_TheoDoi_USD!$B$2:$B$10000, $B17)) | H17: =IF(AND(ISNUMBER(E17), ISNUMBER(G17)), E17-G17, "-") | I17: =IF(AND(ISNUMBER(E17), ISNUMBER(G17), G17<>0), (E17-G17)/G17*100, "-") | AA17: 02/09/2026
B18: Sacombank | C18: =IF(SUMIFS(Data_TheoDoi_USD!$C$2:$C$10000, Data_TheoDoi_USD!$A$2:$A$10000, $B$4, Data_TheoDoi_USD!$B$2:$B$10000, $B18)=0, "-", SUMIFS(Data_TheoDoi_USD!$C$2:$C$10000, Data_TheoDoi_USD!$A$2:$A$10000, $B$4, Data_TheoDoi_USD!$B$2:$B$10000, $B18)) | D18: =IF(SUMIFS(Data_TheoDoi_USD!$D$2:$D$10000, Data_TheoDoi_USD!$A$2:$A$10000, $B$4, Data_TheoDoi_USD!$B$2:$B$10000, $B18)=0, "-", SUMIFS(Data_TheoDoi_USD!$D$2:$D$10000, Data_TheoDoi_USD!$A$2:$A$10000, $B$4, Data_TheoDoi_USD!$B$2:$B$10000, $B18)) | E18: =IF(SUMIFS(Data_TheoDoi_USD!$E$2:$E$10000, Data_TheoDoi_USD!$A$2:$A$10000, $B$4, Data_TheoDoi_USD!$B$2:$B$10000, $B18)=0, "-", SUMIFS(Data_TheoDoi_USD!$E$2:$E$10000, Data_TheoDoi_USD!$A$2:$A$10000, $B$4, Data_TheoDoi_USD!$B$2:$B$10000, $B18)) | F18: =IF(AND(ISNUMBER(E18), ISNUMBER(D18)), E18-D18, "-") | G18: =IF(SUMIFS(Data_TheoDoi_USD!$E$2:$E$10000, Data_TheoDoi_USD!$A$2:$A$10000, $E$4, Data_TheoDoi_USD!$B$2:$B$10000, $B18)=0, "-", SUMIFS(Data_TheoDoi_USD!$E$2:$E$10000, Data_TheoDoi_USD!$A$2:$A$10000, $E$4, Data_TheoDoi_USD!$B$2:$B$10000, $B18)) | H18: =IF(AND(ISNUMBER(E18), ISNUMBER(G18)), E18-G18, "-") | I18: =IF(AND(ISNUMBER(E18), ISNUMBER(G18), G18<>0), (E18-G18)/G18*100, "-") | AA18: 01/09/2026
B19: TPBank | C19: =IF(SUMIFS(Data_TheoDoi_USD!$C$2:$C$10000, Data_TheoDoi_USD!$A$2:$A$10000, $B$4, Data_TheoDoi_USD!$B$2:$B$10000, $B19)=0, "-", SUMIFS(Data_TheoDoi_USD!$C$2:$C$10000, Data_TheoDoi_USD!$A$2:$A$10000, $B$4, Data_TheoDoi_USD!$B$2:$B$10000, $B19)) | D19: =IF(SUMIFS(Data_TheoDoi_USD!$D$2:$D$10000, Data_TheoDoi_USD!$A$2:$A$10000, $B$4, Data_TheoDoi_USD!$B$2:$B$10000, $B19)=0, "-", SUMIFS(Data_TheoDoi_USD!$D$2:$D$10000, Data_TheoDoi_USD!$A$2:$A$10000, $B$4, Data_TheoDoi_USD!$B$2:$B$10000, $B19)) | E19: =IF(SUMIFS(Data_TheoDoi_USD!$E$2:$E$10000, Data_TheoDoi_USD!$A$2:$A$10000, $B$4, Data_TheoDoi_USD!$B$2:$B$10000, $B19)=0, "-", SUMIFS(Data_TheoDoi_USD!$E$2:$E$10000, Data_TheoDoi_USD!$A$2:$A$10000, $B$4, Data_TheoDoi_USD!$B$2:$B$10000, $B19)) | F19: =IF(AND(ISNUMBER(E19), ISNUMBER(D19)), E19-D19, "-") | G19: =IF(SUMIFS(Data_TheoDoi_USD!$E$2:$E$10000, Data_TheoDoi_USD!$A$2:$A$10000, $E$4, Data_TheoDoi_USD!$B$2:$B$10000, $B19)=0, "-", SUMIFS(Data_TheoDoi_USD!$E$2:$E$10000, Data_TheoDoi_USD!$A$2:$A$10000, $E$4, Data_TheoDoi_USD!$B$2:$B$10000, $B19)) | H19: =IF(AND(ISNUMBER(E19), ISNUMBER(G19)), E19-G19, "-") | I19: =IF(AND(ISNUMBER(E19), ISNUMBER(G19), G19<>0), (E19-G19)/G19*100, "-") | AA19: 31/08/2026
B20: VPBank | C20: =IF(SUMIFS(Data_TheoDoi_USD!$C$2:$C$10000, Data_TheoDoi_USD!$A$2:$A$10000, $B$4, Data_TheoDoi_USD!$B$2:$B$10000, $B20)=0, "-", SUMIFS(Data_TheoDoi_USD!$C$2:$C$10000, Data_TheoDoi_USD!$A$2:$A$10000, $B$4, Data_TheoDoi_USD!$B$2:$B$10000, $B20)) | D20: =IF(SUMIFS(Data_TheoDoi_USD!$D$2:$D$10000, Data_TheoDoi_USD!$A$2:$A$10000, $B$4, Data_TheoDoi_USD!$B$2:$B$10000, $B20)=0, "-", SUMIFS(Data_TheoDoi_USD!$D$2:$D$10000, Data_TheoDoi_USD!$A$2:$A$10000, $B$4, Data_TheoDoi_USD!$B$2:$B$10000, $B20)) | E20: =IF(SUMIFS(Data_TheoDoi_USD!$E$2:$E$10000, Data_TheoDoi_USD!$A$2:$A$10000, $B$4, Data_TheoDoi_USD!$B$2:$B$10000, $B20)=0, "-", SUMIFS(Data_TheoDoi_USD!$E$2:$E$10000, Data_TheoDoi_USD!$A$2:$A$10000, $B$4, Data_TheoDoi_USD!$B$2:$B$10000, $B20)) | F20: =IF(AND(ISNUMBER(E20), ISNUMBER(D20)), E20-D20, "-") | G20: =IF(SUMIFS(Data_TheoDoi_USD!$E$2:$E$10000, Data_TheoDoi_USD!$A$2:$A$10000, $E$4, Data_TheoDoi_USD!$B$2:$B$10000, $B20)=0, "-", SUMIFS(Data_TheoDoi_USD!$E$2:$E$10000, Data_TheoDoi_USD!$A$2:$A$10000, $E$4, Data_TheoDoi_USD!$B$2:$B$10000, $B20)) | H20: =IF(AND(ISNUMBER(E20), ISNUMBER(G20)), E20-G20, "-") | I20: =IF(AND(ISNUMBER(E20), ISNUMBER(G20), G20<>0), (E20-G20)/G20*100, "-") | AA20: 30/08/2026
B21: HDBank | C21: =IF(SUMIFS(Data_TheoDoi_USD!$C$2:$C$10000, Data_TheoDoi_USD!$A$2:$A$10000, $B$4, Data_TheoDoi_USD!$B$2:$B$10000, $B21)=0, "-", SUMIFS(Data_TheoDoi_USD!$C$2:$C$10000, Data_TheoDoi_USD!$A$2:$A$10000, $B$4, Data_TheoDoi_USD!$B$2:$B$10000, $B21)) | D21: =IF(SUMIFS(Data_TheoDoi_USD!$D$2:$D$10000, Data_TheoDoi_USD!$A$2:$A$10000, $B$4, Data_TheoDoi_USD!$B$2:$B$10000, $B21)=0, "-", SUMIFS(Data_TheoDoi_USD!$D$2:$D$10000, Data_TheoDoi_USD!$A$2:$A$10000, $B$4, Data_TheoDoi_USD!$B$2:$B$10000, $B21)) | E21: =IF(SUMIFS(Data_TheoDoi_USD!$E$2:$E$10000, Data_TheoDoi_USD!$A$2:$A$10000, $B$4, Data_TheoDoi_USD!$B$2:$B$10000, $B21)=0, "-", SUMIFS(Data_TheoDoi_USD!$E$2:$E$10000, Data_TheoDoi_USD!$A$2:$A$10000, $B$4, Data_TheoDoi_USD!$B$2:$B$10000, $B21)) | F21: =IF(AND(ISNUMBER(E21), ISNUMBER(D21)), E21-D21, "-") | G21: =IF(SUMIFS(Data_TheoDoi_USD!$E$2:$E$10000, Data_TheoDoi_USD!$A$2:$A$10000, $E$4, Data_TheoDoi_USD!$B$2:$B$10000, $B21)=0, "-", SUMIFS(Data_TheoDoi_USD!$E$2:$E$10000, Data_TheoDoi_USD!$A$2:$A$10000, $E$4, Data_TheoDoi_USD!$B$2:$B$10000, $B21)) | H21: =IF(AND(ISNUMBER(E21), ISNUMBER(G21)), E21-G21, "-") | I21: =IF(AND(ISNUMBER(E21), ISNUMBER(G21), G21<>0), (E21-G21)/G21*100, "-") | AA21: 29/08/2026
B22: Eximbank | C22: =IF(SUMIFS(Data_TheoDoi_USD!$C$2:$C$10000, Data_TheoDoi_USD!$A$2:$A$10000, $B$4, Data_TheoDoi_USD!$B$2:$B$10000, $B22)=0, "-", SUMIFS(Data_TheoDoi_USD!$C$2:$C$10000, Data_TheoDoi_USD!$A$2:$A$10000, $B$4, Data_TheoDoi_USD!$B$2:$B$10000, $B22)) | D22: =IF(SUMIFS(Data_TheoDoi_USD!$D$2:$D$10000, Data_TheoDoi_USD!$A$2:$A$10000, $B$4, Data_TheoDoi_USD!$B$2:$B$10000, $B22)=0, "-", SUMIFS(Data_TheoDoi_USD!$D$2:$D$10000, Data_TheoDoi_USD!$A$2:$A$10000, $B$4, Data_TheoDoi_USD!$B$2:$B$10000, $B22)) | E22: =IF(SUMIFS(Data_TheoDoi_USD!$E$2:$E$10000, Data_TheoDoi_USD!$A$2:$A$10000, $B$4, Data_TheoDoi_USD!$B$2:$B$10000, $B22)=0, "-", SUMIFS(Data_TheoDoi_USD!$E$2:$E$10000, Data_TheoDoi_USD!$A$2:$A$10000, $B$4, Data_TheoDoi_USD!$B$2:$B$10000, $B22)) | F22: =IF(AND(ISNUMBER(E22), ISNUMBER(D22)), E22-D22, "-") | G22: =IF(SUMIFS(Data_TheoDoi_USD!$E$2:$E$10000, Data_TheoDoi_USD!$A$2:$A$10000, $E$4, Data_TheoDoi_USD!$B$2:$B$10000, $B22)=0, "-", SUMIFS(Data_TheoDoi_USD!$E$2:$E$10000, Data_TheoDoi_USD!$A$2:$A$10000, $E$4, Data_TheoDoi_USD!$B$2:$B$10000, $B22)) | H22: =IF(AND(ISNUMBER(E22), ISNUMBER(G22)), E22-G22, "-") | I22: =IF(AND(ISNUMBER(E22), ISNUMBER(G22), G22<>0), (E22-G22)/G22*100, "-") | AA22: 28/08/2026
B23: OCB | C23: =IF(SUMIFS(Data_TheoDoi_USD!$C$2:$C$10000, Data_TheoDoi_USD!$A$2:$A$10000, $B$4, Data_TheoDoi_USD!$B$2:$B$10000, $B23)=0, "-", SUMIFS(Data_TheoDoi_USD!$C$2:$C$10000, Data_TheoDoi_USD!$A$2:$A$10000, $B$4, Data_TheoDoi_USD!$B$2:$B$10000, $B23)) | D23: =IF(SUMIFS(Data_TheoDoi_USD!$D$2:$D$10000, Data_TheoDoi_USD!$A$2:$A$10000, $B$4, Data_TheoDoi_USD!$B$2:$B$10000, $B23)=0, "-", SUMIFS(Data_TheoDoi_USD!$D$2:$D$10000, Data_TheoDoi_USD!$A$2:$A$10000, $B$4, Data_TheoDoi_USD!$B$2:$B$10000, $B23)) | E23: =IF(SUMIFS(Data_TheoDoi_USD!$E$2:$E$10000, Data_TheoDoi_USD!$A$2:$A$10000, $B$4, Data_TheoDoi_USD!$B$2:$B$10000, $B23)=0, "-", SUMIFS(Data_TheoDoi_USD!$E$2:$E$10000, Data_TheoDoi_USD!$A$2:$A$10000, $B$4, Data_TheoDoi_USD!$B$2:$B$10000, $B23)) | F23: =IF(AND(ISNUMBER(E23), ISNUMBER(D23)), E23-D23, "-") | G23: =IF(SUMIFS(Data_TheoDoi_USD!$E$2:$E$10000, Data_TheoDoi_USD!$A$2:$A$10000, $E$4, Data_TheoDoi_USD!$B$2:$B$10000, $B23)=0, "-", SUMIFS(Data_TheoDoi_USD!$E$2:$E$10000, Data_TheoDoi_USD!$A$2:$A$10000, $E$4, Data_TheoDoi_USD!$B$2:$B$10000, $B23)) | H23: =IF(AND(ISNUMBER(E23), ISNUMBER(G23)), E23-G23, "-") | I23: =IF(AND(ISNUMBER(E23), ISNUMBER(G23), G23<>0), (E23-G23)/G23*100, "-") | AA23: 27/08/2026
... B26: PVcomBank | C26: =IF(SUMIFS(Data_TheoDoi_USD!$C$2:$C$10000, Data_TheoDoi_USD!$A$2:$A$10000, $B$4, Data_TheoDoi_USD!$B$2:$B$10000, $B26)=0, "-", SUMIFS(Data_TheoDoi_USD!$C$2:$C$10000, Data_TheoDoi_USD!$A$2:$A$10000, $B$4, Data_TheoDoi_USD!$B$2:$B$10000, $B26)) | D26: =IF(SUMIFS(Data_TheoDoi_USD!$D$2:$D$10000, Data_TheoDoi_USD!$A$2:$A$10000, $B$4, Data_TheoDoi_USD!$B$2:$B$10000, $B26)=0, "-", SUMIFS(Data_TheoDoi_USD!$D$2:$D$10000, Data_TheoDoi_USD!$A$2:$A$10000, $B$4, Data_TheoDoi_USD!$B$2:$B$10000, $B26)) | E26: =IF(SUMIFS(Data_TheoDoi_USD!$E$2:$E$10000, Data_TheoDoi_USD!$A$2:$A$10000, $B$4, Data_TheoDoi_USD!$B$2:$B$10000, $B26)=0, "-", SUMIFS(Data_TheoDoi_USD!$E$2:$E$10000, Data_TheoDoi_USD!$A$2:$A$10000, $B$4, Data_TheoDoi_USD!$B$2:$B$10000, $B26)) | F26: =IF(AND(ISNUMBER(E26), ISNUMBER(D26)), E26-D26, "-") | G26: =IF(SUMIFS(Data_TheoDoi_USD!$E$2:$E$10000, Data_TheoDoi_USD!$A$2:$A$10000, $E$4, Data_TheoDoi_USD!$B$2:$B$10000, $B26)=0, "-", SUMIFS(Data_TheoDoi_USD!$E$2:$E$10000, Data_TheoDoi_USD!$A$2:$A$10000, $E$4, Data_TheoDoi_USD!$B$2:$B$10000, $B26)) | H26: =IF(AND(ISNUMBER(E26), ISNUMBER(G26)), E26-G26, "-") | I26: =IF(AND(ISNUMBER(E26), ISNUMBER(G26), G26<>0), (E26-G26)/G26*100, "-") | AA26: 24/08/2026
B27: TRUNG BÌNH THỊ TRƯỜNG | C27: =AVERAGE(C12:C26) | D27: =AVERAGE(D12:D26) | E27: =AVERAGE(E12:E26) | F27: =AVERAGE(F12:F26) | G27: =AVERAGE(G12:G26) | H27: =AVERAGE(H12:H26) | I27: =AVERAGE(I12:I26) | AA27: 23/08/2026
AA28: 22/08/2026
AA29: 21/08/2026
AA30: 20/08/2026
AA31: 19/08/2026
AA32: 18/08/2026
AA33: 17/08/2026
AA34: 16/08/2026
AA35: 15/08/2026
AA36: 14/08/2026
AA37: 13/08/2026
AA38: 12/08/2026
AA39: 11/08/2026
... AA50: 31/07/2026
B51: Nguồn dữ liệu: Vietcombank, VietinBank, BIDV, Agribank (Big 4) và các ngân hàng TMCP hàng đầu Việt Nam | AA51: 30/07/2026
AA52: 29/07/2026
...

Sheet TheoDoi_Thang_USD
AA1: 1 | AB1: Vietcombank
B2: BÁO CÁO TỶ GIÁ USD THEO THÁNG | AA2: 2 | AB2: VietinBank
AA3: 3 | AB3: BIDV
B4: Chọn Năm: | C4: 2026 | E4: Chọn Tháng: | F4: 6 | G4: Ngân Hàng: | H4: Vietcombank | AA4: 4 | AB4: Agribank
AA5: 5 | AB5: Techcombank
B6: STT | C6: Ngày theo lịch | D6: Ngày áp dụng | E6: Mua tiền mặt | F6: Mua chuyển khoản | G6: Bán | H6: Bình quân | AA6: 6 | AB6: ACB
B7: =IF(C7<>"", 1, "") | C7: =IF(MONTH(DATE($C$4, $F$4, 1))=$F$4, DATE($C$4, $F$4, 1), "") | D7: =IF(C7<>"", IF(E7<>"-", C7, "-"), "") | E7: =IF(C7<>"", IF(SUMIFS(Data_TheoDoi_USD!$C$2:$C$10000, Data_TheoDoi_USD!$A$2:$A$10000, TEXT(C7, "dd/mm/yyyy"), Data_TheoDoi_USD!$B$2:$B$10000, $H$4)=0, "-", SUMIFS(Data_TheoDoi_USD!$C$2:$C$10000, Data_TheoDoi_USD!$A$2:$A$10000, TEXT(C7, "dd/mm/yyyy"), Data_TheoDoi_USD!$B$2:$B$10000, $H$4)), "") | F7: =IF(C7<>"", IF(SUMIFS(Data_TheoDoi_USD!$D$2:$D$10000, Data_TheoDoi_USD!$A$2:$A$10000, TEXT(C7, "dd/mm/yyyy"), Data_TheoDoi_USD!$B$2:$B$10000, $H$4)=0, "-", SUMIFS(Data_TheoDoi_USD!$D$2:$D$10000, Data_TheoDoi_USD!$A$2:$A$10000, TEXT(C7, "dd/mm/yyyy"), Data_TheoDoi_USD!$B$2:$B$10000, $H$4)), "") | G7: =IF(C7<>"", IF(SUMIFS(Data_TheoDoi_USD!$E$2:$E$10000, Data_TheoDoi_USD!$A$2:$A$10000, TEXT(C7, "dd/mm/yyyy"), Data_TheoDoi_USD!$B$2:$B$10000, $H$4)=0, "-", SUMIFS(Data_TheoDoi_USD!$E$2:$E$10000, Data_TheoDoi_USD!$A$2:$A$10000, TEXT(C7, "dd/mm/yyyy"), Data_TheoDoi_USD!$B$2:$B$10000, $H$4)), "") | H7: =IF(AND(C7<>"", E7<>"-", F7<>"-", G7<>"-"), IFERROR(AVERAGE(F7, G7), "-"), "") | AA7: 7 | AB7: Sacombank
B8: =IF(C8<>"", 2, "") | C8: =IF(MONTH(DATE($C$4, $F$4, 2))=$F$4, DATE($C$4, $F$4, 2), "") | D8: =IF(C8<>"", IF(E8<>"-", C8, "-"), "") | E8: =IF(C8<>"", IF(SUMIFS(Data_TheoDoi_USD!$C$2:$C$10000, Data_TheoDoi_USD!$A$2:$A$10000, TEXT(C8, "dd/mm/yyyy"), Data_TheoDoi_USD!$B$2:$B$10000, $H$4)=0, "-", SUMIFS(Data_TheoDoi_USD!$C$2:$C$10000, Data_TheoDoi_USD!$A$2:$A$10000, TEXT(C8, "dd/mm/yyyy"), Data_TheoDoi_USD!$B$2:$B$10000, $H$4)), "") | F8: =IF(C8<>"", IF(SUMIFS(Data_TheoDoi_USD!$D$2:$D$10000, Data_TheoDoi_USD!$A$2:$A$10000, TEXT(C8, "dd/mm/yyyy"), Data_TheoDoi_USD!$B$2:$B$10000, $H$4)=0, "-", SUMIFS(Data_TheoDoi_USD!$D$2:$D$10000, Data_TheoDoi_USD!$A$2:$A$10000, TEXT(C8, "dd/mm/yyyy"), Data_TheoDoi_USD!$B$2:$B$10000, $H$4)), "") | G8: =IF(C8<>"", IF(SUMIFS(Data_TheoDoi_USD!$E$2:$E$10000, Data_TheoDoi_USD!$A$2:$A$10000, TEXT(C8, "dd/mm/yyyy"), Data_TheoDoi_USD!$B$2:$B$10000, $H$4)=0, "-", SUMIFS(Data_TheoDoi_USD!$E$2:$E$10000, Data_TheoDoi_USD!$A$2:$A$10000, TEXT(C8, "dd/mm/yyyy"), Data_TheoDoi_USD!$B$2:$B$10000, $H$4)), "") | H8: =IF(AND(C8<>"", E8<>"-", F8<>"-", G8<>"-"), IFERROR(AVERAGE(F8, G8), "-"), "") | AA8: 8 | AB8: TPBank
B9: =IF(C9<>"", 3, "") | C9: =IF(MONTH(DATE($C$4, $F$4, 3))=$F$4, DATE($C$4, $F$4, 3), "") | D9: =IF(C9<>"", IF(E9<>"-", C9, "-"), "") | E9: =IF(C9<>"", IF(SUMIFS(Data_TheoDoi_USD!$C$2:$C$10000, Data_TheoDoi_USD!$A$2:$A$10000, TEXT(C9, "dd/mm/yyyy"), Data_TheoDoi_USD!$B$2:$B$10000, $H$4)=0, "-", SUMIFS(Data_TheoDoi_USD!$C$2:$C$10000, Data_TheoDoi_USD!$A$2:$A$10000, TEXT(C9, "dd/mm/yyyy"), Data_TheoDoi_USD!$B$2:$B$10000, $H$4)), "") | F9: =IF(C9<>"", IF(SUMIFS(Data_TheoDoi_USD!$D$2:$D$10000, Data_TheoDoi_USD!$A$2:$A$10000, TEXT(C9, "dd/mm/yyyy"), Data_TheoDoi_USD!$B$2:$B$10000, $H$4)=0, "-", SUMIFS(Data_TheoDoi_USD!$D$2:$D$10000, Data_TheoDoi_USD!$A$2:$A$10000, TEXT(C9, "dd/mm/yyyy"), Data_TheoDoi_USD!$B$2:$B$10000, $H$4)), "") | G9: =IF(C9<>"", IF(SUMIFS(Data_TheoDoi_USD!$E$2:$E$10000, Data_TheoDoi_USD!$A$2:$A$10000, TEXT(C9, "dd/mm/yyyy"), Data_TheoDoi_USD!$B$2:$B$10000, $H$4)=0, "-", SUMIFS(Data_TheoDoi_USD!$E$2:$E$10000, Data_TheoDoi_USD!$A$2:$A$10000, TEXT(C9, "dd/mm/yyyy"), Data_TheoDoi_USD!$B$2:$B$10000, $H$4)), "") | H9: =IF(AND(C9<>"", E9<>"-", F9<>"-", G9<>"-"), IFERROR(AVERAGE(F9, G9), "-"), "") | AA9: 9 | AB9: VPBank
B10: =IF(C10<>"", 4, "") | C10: =IF(MONTH(DATE($C$4, $F$4, 4))=$F$4, DATE($C$4, $F$4, 4), "") | D10: =IF(C10<>"", IF(E10<>"-", C10, "-"), "") | E10: =IF(C10<>"", IF(SUMIFS(Data_TheoDoi_USD!$C$2:$C$10000, Data_TheoDoi_USD!$A$2:$A$10000, TEXT(C10, "dd/mm/yyyy"), Data_TheoDoi_USD!$B$2:$B$10000, $H$4)=0, "-", SUMIFS(Data_TheoDoi_USD!$C$2:$C$10000, Data_TheoDoi_USD!$A$2:$A$10000, TEXT(C10, "dd/mm/yyyy"), Data_TheoDoi_USD!$B$2:$B$10000, $H$4)), "") | F10: =IF(C10<>"", IF(SUMIFS(Data_TheoDoi_USD!$D$2:$D$10000, Data_TheoDoi_USD!$A$2:$A$10000, TEXT(C10, "dd/mm/yyyy"), Data_TheoDoi_USD!$B$2:$B$10000, $H$4)=0, "-", SUMIFS(Data_TheoDoi_USD!$D$2:$D$10000, Data_TheoDoi_USD!$A$2:$A$10000, TEXT(C10, "dd/mm/yyyy"), Data_TheoDoi_USD!$B$2:$B$10000, $H$4)), "") | G10: =IF(C10<>"", IF(SUMIFS(Data_TheoDoi_USD!$E$2:$E$10000, Data_TheoDoi_USD!$A$2:$A$10000, TEXT(C10, "dd/mm/yyyy"), Data_TheoDoi_USD!$B$2:$B$10000, $H$4)=0, "-", SUMIFS(Data_TheoDoi_USD!$E$2:$E$10000, Data_TheoDoi_USD!$A$2:$A$10000, TEXT(C10, "dd/mm/yyyy"), Data_TheoDoi_USD!$B$2:$B$10000, $H$4)), "") | H10: =IF(AND(C10<>"", E10<>"-", F10<>"-", G10<>"-"), IFERROR(AVERAGE(F10, G10), "-"), "") | AA10: 10 | AB10: HDBank
B11: =IF(C11<>"", 5, "") | C11: =IF(MONTH(DATE($C$4, $F$4, 5))=$F$4, DATE($C$4, $F$4, 5), "") | D11: =IF(C11<>"", IF(E11<>"-", C11, "-"), "") | E11: =IF(C11<>"", IF(SUMIFS(Data_TheoDoi_USD!$C$2:$C$10000, Data_TheoDoi_USD!$A$2:$A$10000, TEXT(C11, "dd/mm/yyyy"), Data_TheoDoi_USD!$B$2:$B$10000, $H$4)=0, "-", SUMIFS(Data_TheoDoi_USD!$C$2:$C$10000, Data_TheoDoi_USD!$A$2:$A$10000, TEXT(C11, "dd/mm/yyyy"), Data_TheoDoi_USD!$B$2:$B$10000, $H$4)), "") | F11: =IF(C11<>"", IF(SUMIFS(Data_TheoDoi_USD!$D$2:$D$10000, Data_TheoDoi_USD!$A$2:$A$10000, TEXT(C11, "dd/mm/yyyy"), Data_TheoDoi_USD!$B$2:$B$10000, $H$4)=0, "-", SUMIFS(Data_TheoDoi_USD!$D$2:$D$10000, Data_TheoDoi_USD!$A$2:$A$10000, TEXT(C11, "dd/mm/yyyy"), Data_TheoDoi_USD!$B$2:$B$10000, $H$4)), "") | G11: =IF(C11<>"", IF(SUMIFS(Data_TheoDoi_USD!$E$2:$E$10000, Data_TheoDoi_USD!$A$2:$A$10000, TEXT(C11, "dd/mm/yyyy"), Data_TheoDoi_USD!$B$2:$B$10000, $H$4)=0, "-", SUMIFS(Data_TheoDoi_USD!$E$2:$E$10000, Data_TheoDoi_USD!$A$2:$A$10000, TEXT(C11, "dd/mm/yyyy"), Data_TheoDoi_USD!$B$2:$B$10000, $H$4)), "") | H11: =IF(AND(C11<>"", E11<>"-", F11<>"-", G11<>"-"), IFERROR(AVERAGE(F11, G11), "-"), "") | AA11: 11 | AB11: Eximbank
B12: =IF(C12<>"", 6, "") | C12: =IF(MONTH(DATE($C$4, $F$4, 6))=$F$4, DATE($C$4, $F$4, 6), "") | D12: =IF(C12<>"", IF(E12<>"-", C12, "-"), "") | E12: =IF(C12<>"", IF(SUMIFS(Data_TheoDoi_USD!$C$2:$C$10000, Data_TheoDoi_USD!$A$2:$A$10000, TEXT(C12, "dd/mm/yyyy"), Data_TheoDoi_USD!$B$2:$B$10000, $H$4)=0, "-", SUMIFS(Data_TheoDoi_USD!$C$2:$C$10000, Data_TheoDoi_USD!$A$2:$A$10000, TEXT(C12, "dd/mm/yyyy"), Data_TheoDoi_USD!$B$2:$B$10000, $H$4)), "") | F12: =IF(C12<>"", IF(SUMIFS(Data_TheoDoi_USD!$D$2:$D$10000, Data_TheoDoi_USD!$A$2:$A$10000, TEXT(C12, "dd/mm/yyyy"), Data_TheoDoi_USD!$B$2:$B$10000, $H$4)=0, "-", SUMIFS(Data_TheoDoi_USD!$D$2:$D$10000, Data_TheoDoi_USD!$A$2:$A$10000, TEXT(C12, "dd/mm/yyyy"), Data_TheoDoi_USD!$B$2:$B$10000, $H$4)), "") | G12: =IF(C12<>"", IF(SUMIFS(Data_TheoDoi_USD!$E$2:$E$10000, Data_TheoDoi_USD!$A$2:$A$10000, TEXT(C12, "dd/mm/yyyy"), Data_TheoDoi_USD!$B$2:$B$10000, $H$4)=0, "-", SUMIFS(Data_TheoDoi_USD!$E$2:$E$10000, Data_TheoDoi_USD!$A$2:$A$10000, TEXT(C12, "dd/mm/yyyy"), Data_TheoDoi_USD!$B$2:$B$10000, $H$4)), "") | H12: =IF(AND(C12<>"", E12<>"-", F12<>"-", G12<>"-"), IFERROR(AVERAGE(F12, G12), "-"), "") | AA12: 12 | AB12: OCB
B13: =IF(C13<>"", 7, "") | C13: =IF(MONTH(DATE($C$4, $F$4, 7))=$F$4, DATE($C$4, $F$4, 7), "") | D13: =IF(C13<>"", IF(E13<>"-", C13, "-"), "") | E13: =IF(C13<>"", IF(SUMIFS(Data_TheoDoi_USD!$C$2:$C$10000, Data_TheoDoi_USD!$A$2:$A$10000, TEXT(C13, "dd/mm/yyyy"), Data_TheoDoi_USD!$B$2:$B$10000, $H$4)=0, "-", SUMIFS(Data_TheoDoi_USD!$C$2:$C$10000, Data_TheoDoi_USD!$A$2:$A$10000, TEXT(C13, "dd/mm/yyyy"), Data_TheoDoi_USD!$B$2:$B$10000, $H$4)), "") | F13: =IF(C13<>"", IF(SUMIFS(Data_TheoDoi_USD!$D$2:$D$10000, Data_TheoDoi_USD!$A$2:$A$10000, TEXT(C13, "dd/mm/yyyy"), Data_TheoDoi_USD!$B$2:$B$10000, $H$4)=0, "-", SUMIFS(Data_TheoDoi_USD!$D$2:$D$10000, Data_TheoDoi_USD!$A$2:$A$10000, TEXT(C13, "dd/mm/yyyy"), Data_TheoDoi_USD!$B$2:$B$10000, $H$4)), "") | G13: =IF(C13<>"", IF(SUMIFS(Data_TheoDoi_USD!$E$2:$E$10000, Data_TheoDoi_USD!$A$2:$A$10000, TEXT(C13, "dd/mm/yyyy"), Data_TheoDoi_USD!$B$2:$B$10000, $H$4)=0, "-", SUMIFS(Data_TheoDoi_USD!$E$2:$E$10000, Data_TheoDoi_USD!$A$2:$A$10000, TEXT(C13, "dd/mm/yyyy"), Data_TheoDoi_USD!$B$2:$B$10000, $H$4)), "") | H13: =IF(AND(C13<>"", E13<>"-", F13<>"-", G13<>"-"), IFERROR(AVERAGE(F13, G13), "-"), "") | AB13: SeaBank
B14: =IF(C14<>"", 8, "") | C14: =IF(MONTH(DATE($C$4, $F$4, 8))=$F$4, DATE($C$4, $F$4, 8), "") | D14: =IF(C14<>"", IF(E14<>"-", C14, "-"), "") | E14: =IF(C14<>"", IF(SUMIFS(Data_TheoDoi_USD!$C$2:$C$10000, Data_TheoDoi_USD!$A$2:$A$10000, TEXT(C14, "dd/mm/yyyy"), Data_TheoDoi_USD!$B$2:$B$10000, $H$4)=0, "-", SUMIFS(Data_TheoDoi_USD!$C$2:$C$10000, Data_TheoDoi_USD!$A$2:$A$10000, TEXT(C14, "dd/mm/yyyy"), Data_TheoDoi_USD!$B$2:$B$10000, $H$4)), "") | F14: =IF(C14<>"", IF(SUMIFS(Data_TheoDoi_USD!$D$2:$D$10000, Data_TheoDoi_USD!$A$2:$A$10000, TEXT(C14, "dd/mm/yyyy"), Data_TheoDoi_USD!$B$2:$B$10000, $H$4)=0, "-", SUMIFS(Data_TheoDoi_USD!$D$2:$D$10000, Data_TheoDoi_USD!$A$2:$A$10000, TEXT(C14, "dd/mm/yyyy"), Data_TheoDoi_USD!$B$2:$B$10000, $H$4)), "") | G14: =IF(C14<>"", IF(SUMIFS(Data_TheoDoi_USD!$E$2:$E$10000, Data_TheoDoi_USD!$A$2:$A$10000, TEXT(C14, "dd/mm/yyyy"), Data_TheoDoi_USD!$B$2:$B$10000, $H$4)=0, "-", SUMIFS(Data_TheoDoi_USD!$E$2:$E$10000, Data_TheoDoi_USD!$A$2:$A$10000, TEXT(C14, "dd/mm/yyyy"), Data_TheoDoi_USD!$B$2:$B$10000, $H$4)), "") | H14: =IF(AND(C14<>"", E14<>"-", F14<>"-", G14<>"-"), IFERROR(AVERAGE(F14, G14), "-"), "") | AB14: VietABank
B15: =IF(C15<>"", 9, "") | C15: =IF(MONTH(DATE($C$4, $F$4, 9))=$F$4, DATE($C$4, $F$4, 9), "") | D15: =IF(C15<>"", IF(E15<>"-", C15, "-"), "") | E15: =IF(C15<>"", IF(SUMIFS(Data_TheoDoi_USD!$C$2:$C$10000, Data_TheoDoi_USD!$A$2:$A$10000, TEXT(C15, "dd/mm/yyyy"), Data_TheoDoi_USD!$B$2:$B$10000, $H$4)=0, "-", SUMIFS(Data_TheoDoi_USD!$C$2:$C$10000, Data_TheoDoi_USD!$A$2:$A$10000, TEXT(C15, "dd/mm/yyyy"), Data_TheoDoi_USD!$B$2:$B$10000, $H$4)), "") | F15: =IF(C15<>"", IF(SUMIFS(Data_TheoDoi_USD!$D$2:$D$10000, Data_TheoDoi_USD!$A$2:$A$10000, TEXT(C15, "dd/mm/yyyy"), Data_TheoDoi_USD!$B$2:$B$10000, $H$4)=0, "-", SUMIFS(Data_TheoDoi_USD!$D$2:$D$10000, Data_TheoDoi_USD!$A$2:$A$10000, TEXT(C15, "dd/mm/yyyy"), Data_TheoDoi_USD!$B$2:$B$10000, $H$4)), "") | G15: =IF(C15<>"", IF(SUMIFS(Data_TheoDoi_USD!$E$2:$E$10000, Data_TheoDoi_USD!$A$2:$A$10000, TEXT(C15, "dd/mm/yyyy"), Data_TheoDoi_USD!$B$2:$B$10000, $H$4)=0, "-", SUMIFS(Data_TheoDoi_USD!$E$2:$E$10000, Data_TheoDoi_USD!$A$2:$A$10000, TEXT(C15, "dd/mm/yyyy"), Data_TheoDoi_USD!$B$2:$B$10000, $H$4)), "") | H15: =IF(AND(C15<>"", E15<>"-", F15<>"-", G15<>"-"), IFERROR(AVERAGE(F15, G15), "-"), "") | AB15: PVcomBank
B16: =IF(C16<>"", 10, "") | C16: =IF(MONTH(DATE($C$4, $F$4, 10))=$F$4, DATE($C$4, $F$4, 10), "") | D16: =IF(C16<>"", IF(E16<>"-", C16, "-"), "") | E16: =IF(C16<>"", IF(SUMIFS(Data_TheoDoi_USD!$C$2:$C$10000, Data_TheoDoi_USD!$A$2:$A$10000, TEXT(C16, "dd/mm/yyyy"), Data_TheoDoi_USD!$B$2:$B$10000, $H$4)=0, "-", SUMIFS(Data_TheoDoi_USD!$C$2:$C$10000, Data_TheoDoi_USD!$A$2:$A$10000, TEXT(C16, "dd/mm/yyyy"), Data_TheoDoi_USD!$B$2:$B$10000, $H$4)), "") | F16: =IF(C16<>"", IF(SUMIFS(Data_TheoDoi_USD!$D$2:$D$10000, Data_TheoDoi_USD!$A$2:$A$10000, TEXT(C16, "dd/mm/yyyy"), Data_TheoDoi_USD!$B$2:$B$10000, $H$4)=0, "-", SUMIFS(Data_TheoDoi_USD!$D$2:$D$10000, Data_TheoDoi_USD!$A$2:$A$10000, TEXT(C16, "dd/mm/yyyy"), Data_TheoDoi_USD!$B$2:$B$10000, $H$4)), "") | G16: =IF(C16<>"", IF(SUMIFS(Data_TheoDoi_USD!$E$2:$E$10000, Data_TheoDoi_USD!$A$2:$A$10000, TEXT(C16, "dd/mm/yyyy"), Data_TheoDoi_USD!$B$2:$B$10000, $H$4)=0, "-", SUMIFS(Data_TheoDoi_USD!$E$2:$E$10000, Data_TheoDoi_USD!$A$2:$A$10000, TEXT(C16, "dd/mm/yyyy"), Data_TheoDoi_USD!$B$2:$B$10000, $H$4)), "") | H16: =IF(AND(C16<>"", E16<>"-", F16<>"-", G16<>"-"), IFERROR(AVERAGE(F16, G16), "-"), "")
B17: =IF(C17<>"", 11, "") | C17: =IF(MONTH(DATE($C$4, $F$4, 11))=$F$4, DATE($C$4, $F$4, 11), "") | D17: =IF(C17<>"", IF(E17<>"-", C17, "-"), "") | E17: =IF(C17<>"", IF(SUMIFS(Data_TheoDoi_USD!$C$2:$C$10000, Data_TheoDoi_USD!$A$2:$A$10000, TEXT(C17, "dd/mm/yyyy"), Data_TheoDoi_USD!$B$2:$B$10000, $H$4)=0, "-", SUMIFS(Data_TheoDoi_USD!$C$2:$C$10000, Data_TheoDoi_USD!$A$2:$A$10000, TEXT(C17, "dd/mm/yyyy"), Data_TheoDoi_USD!$B$2:$B$10000, $H$4)), "") | F17: =IF(C17<>"", IF(SUMIFS(Data_TheoDoi_USD!$D$2:$D$10000, Data_TheoDoi_USD!$A$2:$A$10000, TEXT(C17, "dd/mm/yyyy"), Data_TheoDoi_USD!$B$2:$B$10000, $H$4)=0, "-", SUMIFS(Data_TheoDoi_USD!$D$2:$D$10000, Data_TheoDoi_USD!$A$2:$A$10000, TEXT(C17, "dd/mm/yyyy"), Data_TheoDoi_USD!$B$2:$B$10000, $H$4)), "") | G17: =IF(C17<>"", IF(SUMIFS(Data_TheoDoi_USD!$E$2:$E$10000, Data_TheoDoi_USD!$A$2:$A$10000, TEXT(C17, "dd/mm/yyyy"), Data_TheoDoi_USD!$B$2:$B$10000, $H$4)=0, "-", SUMIFS(Data_TheoDoi_USD!$E$2:$E$10000, Data_TheoDoi_USD!$A$2:$A$10000, TEXT(C17, "dd/mm/yyyy"), Data_TheoDoi_USD!$B$2:$B$10000, $H$4)), "") | H17: =IF(AND(C17<>"", E17<>"-", F17<>"-", G17<>"-"), IFERROR(AVERAGE(F17, G17), "-"), "")
B18: =IF(C18<>"", 12, "") | C18: =IF(MONTH(DATE($C$4, $F$4, 12))=$F$4, DATE($C$4, $F$4, 12), "") | D18: =IF(C18<>"", IF(E18<>"-", C18, "-"), "") | E18: =IF(C18<>"", IF(SUMIFS(Data_TheoDoi_USD!$C$2:$C$10000, Data_TheoDoi_USD!$A$2:$A$10000, TEXT(C18, "dd/mm/yyyy"), Data_TheoDoi_USD!$B$2:$B$10000, $H$4)=0, "-", SUMIFS(Data_TheoDoi_USD!$C$2:$C$10000, Data_TheoDoi_USD!$A$2:$A$10000, TEXT(C18, "dd/mm/yyyy"), Data_TheoDoi_USD!$B$2:$B$10000, $H$4)), "") | F18: =IF(C18<>"", IF(SUMIFS(Data_TheoDoi_USD!$D$2:$D$10000, Data_TheoDoi_USD!$A$2:$A$10000, TEXT(C18, "dd/mm/yyyy"), Data_TheoDoi_USD!$B$2:$B$10000, $H$4)=0, "-", SUMIFS(Data_TheoDoi_USD!$D$2:$D$10000, Data_TheoDoi_USD!$A$2:$A$10000, TEXT(C18, "dd/mm/yyyy"), Data_TheoDoi_USD!$B$2:$B$10000, $H$4)), "") | G18: =IF(C18<>"", IF(SUMIFS(Data_TheoDoi_USD!$E$2:$E$10000, Data_TheoDoi_USD!$A$2:$A$10000, TEXT(C18, "dd/mm/yyyy"), Data_TheoDoi_USD!$B$2:$B$10000, $H$4)=0, "-", SUMIFS(Data_TheoDoi_USD!$E$2:$E$10000, Data_TheoDoi_USD!$A$2:$A$10000, TEXT(C18, "dd/mm/yyyy"), Data_TheoDoi_USD!$B$2:$B$10000, $H$4)), "") | H18: =IF(AND(C18<>"", E18<>"-", F18<>"-", G18<>"-"), IFERROR(AVERAGE(F18, G18), "-"), "")
B19: =IF(C19<>"", 13, "") | C19: =IF(MONTH(DATE($C$4, $F$4, 13))=$F$4, DATE($C$4, $F$4, 13), "") | D19: =IF(C19<>"", IF(E19<>"-", C19, "-"), "") | E19: =IF(C19<>"", IF(SUMIFS(Data_TheoDoi_USD!$C$2:$C$10000, Data_TheoDoi_USD!$A$2:$A$10000, TEXT(C19, "dd/mm/yyyy"), Data_TheoDoi_USD!$B$2:$B$10000, $H$4)=0, "-", SUMIFS(Data_TheoDoi_USD!$C$2:$C$10000, Data_TheoDoi_USD!$A$2:$A$10000, TEXT(C19, "dd/mm/yyyy"), Data_TheoDoi_USD!$B$2:$B$10000, $H$4)), "") | F19: =IF(C19<>"", IF(SUMIFS(Data_TheoDoi_USD!$D$2:$D$10000, Data_TheoDoi_USD!$A$2:$A$10000, TEXT(C19, "dd/mm/yyyy"), Data_TheoDoi_USD!$B$2:$B$10000, $H$4)=0, "-", SUMIFS(Data_TheoDoi_USD!$D$2:$D$10000, Data_TheoDoi_USD!$A$2:$A$10000, TEXT(C19, "dd/mm/yyyy"), Data_TheoDoi_USD!$B$2:$B$10000, $H$4)), "") | G19: =IF(C19<>"", IF(SUMIFS(Data_TheoDoi_USD!$E$2:$E$10000, Data_TheoDoi_USD!$A$2:$A$10000, TEXT(C19, "dd/mm/yyyy"), Data_TheoDoi_USD!$B$2:$B$10000, $H$4)=0, "-", SUMIFS(Data_TheoDoi_USD!$E$2:$E$10000, Data_TheoDoi_USD!$A$2:$A$10000, TEXT(C19, "dd/mm/yyyy"), Data_TheoDoi_USD!$B$2:$B$10000, $H$4)), "") | H19: =IF(AND(C19<>"", E19<>"-", F19<>"-", G19<>"-"), IFERROR(AVERAGE(F19, G19), "-"), "")
B20: =IF(C20<>"", 14, "") | C20: =IF(MONTH(DATE($C$4, $F$4, 14))=$F$4, DATE($C$4, $F$4, 14), "") | D20: =IF(C20<>"", IF(E20<>"-", C20, "-"), "") | E20: =IF(C20<>"", IF(SUMIFS(Data_TheoDoi_USD!$C$2:$C$10000, Data_TheoDoi_USD!$A$2:$A$10000, TEXT(C20, "dd/mm/yyyy"), Data_TheoDoi_USD!$B$2:$B$10000, $H$4)=0, "-", SUMIFS(Data_TheoDoi_USD!$C$2:$C$10000, Data_TheoDoi_USD!$A$2:$A$10000, TEXT(C20, "dd/mm/yyyy"), Data_TheoDoi_USD!$B$2:$B$10000, $H$4)), "") | F20: =IF(C20<>"", IF(SUMIFS(Data_TheoDoi_USD!$D$2:$D$10000, Data_TheoDoi_USD!$A$2:$A$10000, TEXT(C20, "dd/mm/yyyy"), Data_TheoDoi_USD!$B$2:$B$10000, $H$4)=0, "-", SUMIFS(Data_TheoDoi_USD!$D$2:$D$10000, Data_TheoDoi_USD!$A$2:$A$10000, TEXT(C20, "dd/mm/yyyy"), Data_TheoDoi_USD!$B$2:$B$10000, $H$4)), "") | G20: =IF(C20<>"", IF(SUMIFS(Data_TheoDoi_USD!$E$2:$E$10000, Data_TheoDoi_USD!$A$2:$A$10000, TEXT(C20, "dd/mm/yyyy"), Data_TheoDoi_USD!$B$2:$B$10000, $H$4)=0, "-", SUMIFS(Data_TheoDoi_USD!$E$2:$E$10000, Data_TheoDoi_USD!$A$2:$A$10000, TEXT(C20, "dd/mm/yyyy"), Data_TheoDoi_USD!$B$2:$B$10000, $H$4)), "") | H20: =IF(AND(C20<>"", E20<>"-", F20<>"-", G20<>"-"), IFERROR(AVERAGE(F20, G20), "-"), "")
B21: =IF(C21<>"", 15, "") | C21: =IF(MONTH(DATE($C$4, $F$4, 15))=$F$4, DATE($C$4, $F$4, 15), "") | D21: =IF(C21<>"", IF(E21<>"-", C21, "-"), "") | E21: =IF(C21<>"", IF(SUMIFS(Data_TheoDoi_USD!$C$2:$C$10000, Data_TheoDoi_USD!$A$2:$A$10000, TEXT(C21, "dd/mm/yyyy"), Data_TheoDoi_USD!$B$2:$B$10000, $H$4)=0, "-", SUMIFS(Data_TheoDoi_USD!$C$2:$C$10000, Data_TheoDoi_USD!$A$2:$A$10000, TEXT(C21, "dd/mm/yyyy"), Data_TheoDoi_USD!$B$2:$B$10000, $H$4)), "") | F21: =IF(C21<>"", IF(SUMIFS(Data_TheoDoi_USD!$D$2:$D$10000, Data_TheoDoi_USD!$A$2:$A$10000, TEXT(C21, "dd/mm/yyyy"), Data_TheoDoi_USD!$B$2:$B$10000, $H$4)=0, "-", SUMIFS(Data_TheoDoi_USD!$D$2:$D$10000, Data_TheoDoi_USD!$A$2:$A$10000, TEXT(C21, "dd/mm/yyyy"), Data_TheoDoi_USD!$B$2:$B$10000, $H$4)), "") | G21: =IF(C21<>"", IF(SUMIFS(Data_TheoDoi_USD!$E$2:$E$10000, Data_TheoDoi_USD!$A$2:$A$10000, TEXT(C21, "dd/mm/yyyy"), Data_TheoDoi_USD!$B$2:$B$10000, $H$4)=0, "-", SUMIFS(Data_TheoDoi_USD!$E$2:$E$10000, Data_TheoDoi_USD!$A$2:$A$10000, TEXT(C21, "dd/mm/yyyy"), Data_TheoDoi_USD!$B$2:$B$10000, $H$4)), "") | H21: =IF(AND(C21<>"", E21<>"-", F21<>"-", G21<>"-"), IFERROR(AVERAGE(F21, G21), "-"), "")
B22: =IF(C22<>"", 16, "") | C22: =IF(MONTH(DATE($C$4, $F$4, 16))=$F$4, DATE($C$4, $F$4, 16), "") | D22: =IF(C22<>"", IF(E22<>"-", C22, "-"), "") | E22: =IF(C22<>"", IF(SUMIFS(Data_TheoDoi_USD!$C$2:$C$10000, Data_TheoDoi_USD!$A$2:$A$10000, TEXT(C22, "dd/mm/yyyy"), Data_TheoDoi_USD!$B$2:$B$10000, $H$4)=0, "-", SUMIFS(Data_TheoDoi_USD!$C$2:$C$10000, Data_TheoDoi_USD!$A$2:$A$10000, TEXT(C22, "dd/mm/yyyy"), Data_TheoDoi_USD!$B$2:$B$10000, $H$4)), "") | F22: =IF(C22<>"", IF(SUMIFS(Data_TheoDoi_USD!$D$2:$D$10000, Data_TheoDoi_USD!$A$2:$A$10000, TEXT(C22, "dd/mm/yyyy"), Data_TheoDoi_USD!$B$2:$B$10000, $H$4)=0, "-", SUMIFS(Data_TheoDoi_USD!$D$2:$D$10000, Data_TheoDoi_USD!$A$2:$A$10000, TEXT(C22, "dd/mm/yyyy"), Data_TheoDoi_USD!$B$2:$B$10000, $H$4)), "") | G22: =IF(C22<>"", IF(SUMIFS(Data_TheoDoi_USD!$E$2:$E$10000, Data_TheoDoi_USD!$A$2:$A$10000, TEXT(C22, "dd/mm/yyyy"), Data_TheoDoi_USD!$B$2:$B$10000, $H$4)=0, "-", SUMIFS(Data_TheoDoi_USD!$E$2:$E$10000, Data_TheoDoi_USD!$A$2:$A$10000, TEXT(C22, "dd/mm/yyyy"), Data_TheoDoi_USD!$B$2:$B$10000, $H$4)), "") | H22: =IF(AND(C22<>"", E22<>"-", F22<>"-", G22<>"-"), IFERROR(AVERAGE(F22, G22), "-"), "")
B23: =IF(C23<>"", 17, "") | C23: =IF(MONTH(DATE($C$4, $F$4, 17))=$F$4, DATE($C$4, $F$4, 17), "") | D23: =IF(C23<>"", IF(E23<>"-", C23, "-"), "") | E23: =IF(C23<>"", IF(SUMIFS(Data_TheoDoi_USD!$C$2:$C$10000, Data_TheoDoi_USD!$A$2:$A$10000, TEXT(C23, "dd/mm/yyyy"), Data_TheoDoi_USD!$B$2:$B$10000, $H$4)=0, "-", SUMIFS(Data_TheoDoi_USD!$C$2:$C$10000, Data_TheoDoi_USD!$A$2:$A$10000, TEXT(C23, "dd/mm/yyyy"), Data_TheoDoi_USD!$B$2:$B$10000, $H$4)), "") | F23: =IF(C23<>"", IF(SUMIFS(Data_TheoDoi_USD!$D$2:$D$10000, Data_TheoDoi_USD!$A$2:$A$10000, TEXT(C23, "dd/mm/yyyy"), Data_TheoDoi_USD!$B$2:$B$10000, $H$4)=0, "-", SUMIFS(Data_TheoDoi_USD!$D$2:$D$10000, Data_TheoDoi_USD!$A$2:$A$10000, TEXT(C23, "dd/mm/yyyy"), Data_TheoDoi_USD!$B$2:$B$10000, $H$4)), "") | G23: =IF(C23<>"", IF(SUMIFS(Data_TheoDoi_USD!$E$2:$E$10000, Data_TheoDoi_USD!$A$2:$A$10000, TEXT(C23, "dd/mm/yyyy"), Data_TheoDoi_USD!$B$2:$B$10000, $H$4)=0, "-", SUMIFS(Data_TheoDoi_USD!$E$2:$E$10000, Data_TheoDoi_USD!$A$2:$A$10000, TEXT(C23, "dd/mm/yyyy"), Data_TheoDoi_USD!$B$2:$B$10000, $H$4)), "") | H23: =IF(AND(C23<>"", E23<>"-", F23<>"-", G23<>"-"), IFERROR(AVERAGE(F23, G23), "-"), "")
B24: =IF(C24<>"", 18, "") | C24: =IF(MONTH(DATE($C$4, $F$4, 18))=$F$4, DATE($C$4, $F$4, 18), "") | D24: =IF(C24<>"", IF(E24<>"-", C24, "-"), "") | E24: =IF(C24<>"", IF(SUMIFS(Data_TheoDoi_USD!$C$2:$C$10000, Data_TheoDoi_USD!$A$2:$A$10000, TEXT(C24, "dd/mm/yyyy"), Data_TheoDoi_USD!$B$2:$B$10000, $H$4)=0, "-", SUMIFS(Data_TheoDoi_USD!$C$2:$C$10000, Data_TheoDoi_USD!$A$2:$A$10000, TEXT(C24, "dd/mm/yyyy"), Data_TheoDoi_USD!$B$2:$B$10000, $H$4)), "") | F24: =IF(C24<>"", IF(SUMIFS(Data_TheoDoi_USD!$D$2:$D$10000, Data_TheoDoi_USD!$A$2:$A$10000, TEXT(C24, "dd/mm/yyyy"), Data_TheoDoi_USD!$B$2:$B$10000, $H$4)=0, "-", SUMIFS(Data_TheoDoi_USD!$D$2:$D$10000, Data_TheoDoi_USD!$A$2:$A$10000, TEXT(C24, "dd/mm/yyyy"), Data_TheoDoi_USD!$B$2:$B$10000, $H$4)), "") | G24: =IF(C24<>"", IF(SUMIFS(Data_TheoDoi_USD!$E$2:$E$10000, Data_TheoDoi_USD!$A$2:$A$10000, TEXT(C24, "dd/mm/yyyy"), Data_TheoDoi_USD!$B$2:$B$10000, $H$4)=0, "-", SUMIFS(Data_TheoDoi_USD!$E$2:$E$10000, Data_TheoDoi_USD!$A$2:$A$10000, TEXT(C24, "dd/mm/yyyy"), Data_TheoDoi_USD!$B$2:$B$10000, $H$4)), "") | H24: =IF(AND(C24<>"", E24<>"-", F24<>"-", G24<>"-"), IFERROR(AVERAGE(F24, G24), "-"), "")
B25: =IF(C25<>"", 19, "") | C25: =IF(MONTH(DATE($C$4, $F$4, 19))=$F$4, DATE($C$4, $F$4, 19), "") | D25: =IF(C25<>"", IF(E25<>"-", C25, "-"), "") | E25: =IF(C25<>"", IF(SUMIFS(Data_TheoDoi_USD!$C$2:$C$10000, Data_TheoDoi_USD!$A$2:$A$10000, TEXT(C25, "dd/mm/yyyy"), Data_TheoDoi_USD!$B$2:$B$10000, $H$4)=0, "-", SUMIFS(Data_TheoDoi_USD!$C$2:$C$10000, Data_TheoDoi_USD!$A$2:$A$10000, TEXT(C25, "dd/mm/yyyy"), Data_TheoDoi_USD!$B$2:$B$10000, $H$4)), "") | F25: =IF(C25<>"", IF(SUMIFS(Data_TheoDoi_USD!$D$2:$D$10000, Data_TheoDoi_USD!$A$2:$A$10000, TEXT(C25, "dd/mm/yyyy"), Data_TheoDoi_USD!$B$2:$B$10000, $H$4)=0, "-", SUMIFS(Data_TheoDoi_USD!$D$2:$D$10000, Data_TheoDoi_USD!$A$2:$A$10000, TEXT(C25, "dd/mm/yyyy"), Data_TheoDoi_USD!$B$2:$B$10000, $H$4)), "") | G25: =IF(C25<>"", IF(SUMIFS(Data_TheoDoi_USD!$E$2:$E$10000, Data_TheoDoi_USD!$A$2:$A$10000, TEXT(C25, "dd/mm/yyyy"), Data_TheoDoi_USD!$B$2:$B$10000, $H$4)=0, "-", SUMIFS(Data_TheoDoi_USD!$E$2:$E$10000, Data_TheoDoi_USD!$A$2:$A$10000, TEXT(C25, "dd/mm/yyyy"), Data_TheoDoi_USD!$B$2:$B$10000, $H$4)), "") | H25: =IF(AND(C25<>"", E25<>"-", F25<>"-", G25<>"-"), IFERROR(AVERAGE(F25, G25), "-"), "")
B26: =IF(C26<>"", 20, "") | C26: =IF(MONTH(DATE($C$4, $F$4, 20))=$F$4, DATE($C$4, $F$4, 20), "") | D26: =IF(C26<>"", IF(E26<>"-", C26, "-"), "") | E26: =IF(C26<>"", IF(SUMIFS(Data_TheoDoi_USD!$C$2:$C$10000, Data_TheoDoi_USD!$A$2:$A$10000, TEXT(C26, "dd/mm/yyyy"), Data_TheoDoi_USD!$B$2:$B$10000, $H$4)=0, "-", SUMIFS(Data_TheoDoi_USD!$C$2:$C$10000, Data_TheoDoi_USD!$A$2:$A$10000, TEXT(C26, "dd/mm/yyyy"), Data_TheoDoi_USD!$B$2:$B$10000, $H$4)), "") | F26: =IF(C26<>"", IF(SUMIFS(Data_TheoDoi_USD!$D$2:$D$10000, Data_TheoDoi_USD!$A$2:$A$10000, TEXT(C26, "dd/mm/yyyy"), Data_TheoDoi_USD!$B$2:$B$10000, $H$4)=0, "-", SUMIFS(Data_TheoDoi_USD!$D$2:$D$10000, Data_TheoDoi_USD!$A$2:$A$10000, TEXT(C26, "dd/mm/yyyy"), Data_TheoDoi_USD!$B$2:$B$10000, $H$4)), "") | G26: =IF(C26<>"", IF(SUMIFS(Data_TheoDoi_USD!$E$2:$E$10000, Data_TheoDoi_USD!$A$2:$A$10000, TEXT(C26, "dd/mm/yyyy"), Data_TheoDoi_USD!$B$2:$B$10000, $H$4)=0, "-", SUMIFS(Data_TheoDoi_USD!$E$2:$E$10000, Data_TheoDoi_USD!$A$2:$A$10000, TEXT(C26, "dd/mm/yyyy"), Data_TheoDoi_USD!$B$2:$B$10000, $H$4)), "") | H26: =IF(AND(C26<>"", E26<>"-", F26<>"-", G26<>"-"), IFERROR(AVERAGE(F26, G26), "-"), "")
B27: =IF(C27<>"", 21, "") | C27: =IF(MONTH(DATE($C$4, $F$4, 21))=$F$4, DATE($C$4, $F$4, 21), "") | D27: =IF(C27<>"", IF(E27<>"-", C27, "-"), "") | E27: =IF(C27<>"", IF(SUMIFS(Data_TheoDoi_USD!$C$2:$C$10000, Data_TheoDoi_USD!$A$2:$A$10000, TEXT(C27, "dd/mm/yyyy"), Data_TheoDoi_USD!$B$2:$B$10000, $H$4)=0, "-", SUMIFS(Data_TheoDoi_USD!$C$2:$C$10000, Data_TheoDoi_USD!$A$2:$A$10000, TEXT(C27, "dd/mm/yyyy"), Data_TheoDoi_USD!$B$2:$B$10000, $H$4)), "") | F27: =IF(C27<>"", IF(SUMIFS(Data_TheoDoi_USD!$D$2:$D$10000, Data_TheoDoi_USD!$A$2:$A$10000, TEXT(C27, "dd/mm/yyyy"), Data_TheoDoi_USD!$B$2:$B$10000, $H$4)=0, "-", SUMIFS(Data_TheoDoi_USD!$D$2:$D$10000, Data_TheoDoi_USD!$A$2:$A$10000, TEXT(C27, "dd/mm/yyyy"), Data_TheoDoi_USD!$B$2:$B$10000, $H$4)), "") | G27: =IF(C27<>"", IF(SUMIFS(Data_TheoDoi_USD!$E$2:$E$10000, Data_TheoDoi_USD!$A$2:$A$10000, TEXT(C27, "dd/mm/yyyy"), Data_TheoDoi_USD!$B$2:$B$10000, $H$4)=0, "-", SUMIFS(Data_TheoDoi_USD!$E$2:$E$10000, Data_TheoDoi_USD!$A$2:$A$10000, TEXT(C27, "dd/mm/yyyy"), Data_TheoDoi_USD!$B$2:$B$10000, $H$4)), "") | H27: =IF(AND(C27<>"", E27<>"-", F27<>"-", G27<>"-"), IFERROR(AVERAGE(F27, G27), "-"), "")
